Workbook
Name Print_Area_Reset: OFFSET(Full_Print,0,0,Last_Row)
Name Print_Area_Reset: OFFSET(Full_Print,0,0,Last_Row)
Name Print_Area_Reset: OFFSET(Full_Print,0,0,Last_Row)
Name Print_Area_Reset: OFFSET(Full_Print,0,0,Last_Row)
Name Print_Area_Reset: OFFSET(Full_Print,0,0,Last_Row)
Name Print_Area_Reset: OFFSET(Full_Print,0,0,Last_Row)
Name Print_Area_Reset: OFFSET(Full_Print,0,0,Last_Row)
Name PrintRange1: [0]!IQRCIQIDH405("Chart of Accounts","F",2,"J")
Name PrintRange2: [0]!IQRCIQIDH405("Account Balances","F",2,"J")
Name PrintRange6: [0]!IQRCIQIDH405("Debtors Inquiry","F",2,"L")
Name PrintRange8: [0]!IQRCIQIDH405("P&L Forecast","F",2,"T")
Name PrintRange9: [0]!IQRCIQIDH405("Trial Balance","F",2,"M")

Sheet RPL>>
D8: Project X
D9: CLIENT
D10: Recast Statement of Operations

Sheet RPL1
A1: =IF(ROUND(SUM(E37:AR37),1)<>0,"NO","Yes") -> Yes | C1: Project X
A2: =IF(COUNTIF(E37:AR37,">0.5")+COUNTIF(E37:AR37,"<-0.5")<1,"Yes","No") -> Yes | C2: CLIENT
A3: =2-COUNTIF(A1:A2,"Yes") -> 0 | C3: ($ in 000s)
C4: Recast Statement of Operations
C7: =C4 -> Recast Statement of Operations | E7: FY24 | Q7: FY25 | AC7: FY26 | AM7: =AI8 -> 45961 | AO7: % of revenue
C8: =C3 -> ($ in 000s) | D8: Ref | E8: 45046 | F8: 45077 | G8: 45107 | H8: 45138 | I8: 45169 | J8: 45199 | K8: 45230 | L8: 45260 | M8: 45291 | N8: 45322 | O8: 45351 | P8: 45382 | Q8: 45412 | R8: 45443 | S8: 45473 | T8: 45504 | U8: 45535 | V8: 45565 | W8: 45596 | X8: 45626 | Y8: 45657 | Z8: 45688 | AA8: 45716 | AB8: 45747 | AC8: 45777 | AD8: 45808 | AE8: 45838 | AF8: 45869 | AG8: 45900 | AH8: 45930 | AI8: 45961 | AK8: FY24 | AL8: FY25 | AM8: TTM26 | AO8: =+AK8 -> FY24 | AP8: =+AL8 -> FY25 | AQ8: =+AM8 -> TTM26
C9: Service revenue | E9: =_xlfn.XLOOKUP($C9,'PL1'!$C:$C,'PL1'!E:E)+SUMIFS(ADJ!G:G,ADJ!$E:$E,'RPL1'!$C9) -> 193.127 | F9: =_xlfn.XLOOKUP($C9,'PL1'!$C:$C,'PL1'!F:F)+SUMIFS(ADJ!H:H,ADJ!$E:$E,'RPL1'!$C9) -> 429.4435 | G9: =_xlfn.XLOOKUP($C9,'PL1'!$C:$C,'PL1'!G:G)+SUMIFS(ADJ!I:I,ADJ!$E:$E,'RPL1'!$C9) -> 731.815 | H9: =_xlfn.XLOOKUP($C9,'PL1'!$C:$C,'PL1'!H:H)+SUMIFS(ADJ!J:J,ADJ!$E:$E,'RPL1'!$C9) -> 430.355 | I9: =_xlfn.XLOOKUP($C9,'PL1'!$C:$C,'PL1'!I:I)+SUMIFS(ADJ!K:K,ADJ!$E:$E,'RPL1'!$C9) -> 623.429 | J9: =_xlfn.XLOOKUP($C9,'PL1'!$C:$C,'PL1'!J:J)+SUMIFS(ADJ!L:L,ADJ!$E:$E,'RPL1'!$C9) -> 480.831 | K9: =_xlfn.XLOOKUP($C9,'PL1'!$C:$C,'PL1'!K:K)+SUMIFS(ADJ!M:M,ADJ!$E:$E,'RPL1'!$C9) -> 688.468 | L9: =_xlfn.XLOOKUP($C9,'PL1'!$C:$C,'PL1'!L:L)+SUMIFS(ADJ!N:N,ADJ!$E:$E,'RPL1'!$C9) -> 1267.3995 | M9: =_xlfn.XLOOKUP($C9,'PL1'!$C:$C,'PL1'!M:M)+SUMIFS(ADJ!O:O,ADJ!$E:$E,'RPL1'!$C9) -> 1276.176 | N9: =_xlfn.XLOOKUP($C9,'PL1'!$C:$C,'PL1'!N:N)+SUMIFS(ADJ!P:P,ADJ!$E:$E,'RPL1'!$C9) -> 238.7015 | O9: =_xlfn.XLOOKUP($C9,'PL1'!$C:$C,'PL1'!O:O)+SUMIFS(ADJ!Q:Q,ADJ!$E:$E,'RPL1'!$C9) -> 550.8931 | P9: =_xlfn.XLOOKUP($C9,'PL1'!$C:$C,'PL1'!P:P)+SUMIFS(ADJ!R:R,ADJ!$E:$E,'RPL1'!$C9) -> 736.783 | Q9: =_xlfn.XLOOKUP($C9,'PL1'!$C:$C,'PL1'!Q:Q)+SUMIFS(ADJ!S:S,ADJ!$E:$E,'RPL1'!$C9) -> 422.044 | R9: =_xlfn.XLOOKUP($C9,'PL1'!$C:$C,'PL1'!R:R)+SUMIFS(ADJ!T:T,ADJ!$E:$E,'RPL1'!$C9) -> 525.65 | S9: =_xlfn.XLOOKUP($C9,'PL1'!$C:$C,'PL1'!S:S)+SUMIFS(ADJ!U:U,ADJ!$E:$E,'RPL1'!$C9) -> 371.348 | T9: =_xlfn.XLOOKUP($C9,'PL1'!$C:$C,'PL1'!T:T)+SUMIFS(ADJ!V:V,ADJ!$E:$E,'RPL1'!$C9) -> 381.634 | U9: =_xlfn.XLOOKUP($C9,'PL1'!$C:$C,'PL1'!U:U)+SUMIFS(ADJ!W:W,ADJ!$E:$E,'RPL1'!$C9) -> 537.179 | V9: =_xlfn.XLOOKUP($C9,'PL1'!$C:$C,'PL1'!V:V)+SUMIFS(ADJ!X:X,ADJ!$E:$E,'RPL1'!$C9) -> 356.904 | W9: =_xlfn.XLOOKUP($C9,'PL1'!$C:$C,'PL1'!W:W)+SUMIFS(ADJ!Y:Y,ADJ!$E:$E,'RPL1'!$C9) -> 365.614 | X9: =_xlfn.XLOOKUP($C9,'PL1'!$C:$C,'PL1'!X:X)+SUMIFS(ADJ!Z:Z,ADJ!$E:$E,'RPL1'!$C9) -> 1132.402 | Y9: =_xlfn.XLOOKUP($C9,'PL1'!$C:$C,'PL1'!Y:Y)+SUMIFS(ADJ!AA:AA,ADJ!$E:$E,'RPL1'!$C9) -> 1135.1701 | Z9: =_xlfn.XLOOKUP($C9,'PL1'!$C:$C,'PL1'!Z:Z)+SUMIFS(ADJ!AB:AB,ADJ!$E:$E,'RPL1'!$C9) -> 329.65101 | AA9: =_xlfn.XLOOKUP($C9,'PL1'!$C:$C,'PL1'!AA:AA)+SUMIFS(ADJ!AC:AC,ADJ!$E:$E,'RPL1'!$C9) -> 807.929 | AB9: =_xlfn.XLOOKUP($C9,'PL1'!$C:$C,'PL1'!AB:AB)+SUMIFS(ADJ!AD:AD,ADJ!$E:$E,'RPL1'!$C9) -> 413.22601 | AC9: =_xlfn.XLOOKUP($C9,'PL1'!$C:$C,'PL1'!AC:AC)+SUMIFS(ADJ!AE:AE,ADJ!$E:$E,'RPL1'!$C9) -> 351.473 | AD9: =_xlfn.XLOOKUP($C9,'PL1'!$C:$C,'PL1'!AD:AD)+SUMIFS(ADJ!AF:AF,ADJ!$E:$E,'RPL1'!$C9) -> 543.607 | AE9: =_xlfn.XLOOKUP($C9,'PL1'!$C:$C,'PL1'!AE:AE)+SUMIFS(ADJ!AG:AG,ADJ!$E:$E,'RPL1'!$C9) -> 736.5651 | AF9: =_xlfn.XLOOKUP($C9,'PL1'!$C:$C,'PL1'!AF:AF)+SUMIFS(ADJ!AH:AH,ADJ!$E:$E,'RPL1'!$C9) -> 425.647 | AG9: =_xlfn.XLOOKUP($C9,'PL1'!$C:$C,'PL1'!AG:AG)+SUMIFS(ADJ!AI:AI,ADJ!$E:$E,'RPL1'!$C9) -> 284.19 | AH9: =_xlfn.XLOOKUP($C9,'PL1'!$C:$C,'PL1'!AH:AH)+SUMIFS(ADJ!AJ:AJ,ADJ!$E:$E,'RPL1'!$C9) -> 760.366 | AI9: =_xlfn.XLOOKUP($C9,'PL1'!$C:$C,'PL1'!AI:AI)+SUMIFS(ADJ!AK:AK,ADJ!$E:$E,'RPL1'!$C9) -> 423.188 | AK9: =SUM(E9:P9) -> 7647.4216 | AL9: =SUM(Q9:AB9) -> 6778.7512 | AM9: =SUM(X9:AI9) -> 7343.4143 | AO9: =IFERROR(AK9/AK$10%,0) -> 100 | AP9: =IFERROR(AL9/AL$10%,0) -> 100 | AQ9: =IFERROR(AM9/AM$10%,0) -> 100
C10: Net revenue | E10: =SUM(E9:E9) -> 193.127 | F10: =SUM(F9:F9) -> 429.4435 | G10: =SUM(G9:G9) -> 731.815 | H10: =SUM(H9:H9) -> 430.355 | I10: =SUM(I9:I9) -> 623.429 | J10: =SUM(J9:J9) -> 480.831 | K10: =SUM(K9:K9) -> 688.468 | L10: =SUM(L9:L9) -> 1267.3995 | ... AI10: =SUM(AI9:AI9) -> 423.188 | AK10: =SUM(AK9:AK9) -> 7647.4216 | AL10: =SUM(AL9:AL9) -> 6778.7512 | AM10: =SUM(AM9:AM9) -> 7343.4143 | AO10: =IFERROR(AK10/AK$10%,0) -> 100 | AP10: =IFERROR(AL10/AL$10%,0) -> 100 | AQ10: =IFERROR(AM10/AM$10%,0) -> 100
C12: YoY Growth (%) | E12: n/a | F12: n/a | G12: n/a | H12: n/a | I12: n/a | J12: n/a | K12: n/a | L12: n/a | M12: n/a | N12: n/a | O12: n/a | P12: n/a | Q12: =IFERROR(Q10/E10%-100,0) -> 118.53185 | R12: =IFERROR(R10/F10%-100,0) -> 22.402598 | S12: =IFERROR(S10/G10%-100,0) -> -49.256574 | T12: =IFERROR(T10/H10%-100,0) -> -11.321119 | U12: =IFERROR(U10/I10%-100,0) -> -13.834775 | V12: =IFERROR(V10/J10%-100,0) -> -25.773505 | W12: =IFERROR(W10/K10%-100,0) -> -46.894554 | X12: =IFERROR(X10/L10%-100,0) -> -10.651535 | ... AI12: =IFERROR(AI10/W10%-100,0) -> 15.747209 | AK12: n/a | AL12: =IFERROR(AL10/AK10%-100,0) -> -11.358998 | AM12: =IFERROR(AM10/SUM(L10:W10)%-100,0) -> 4.4533946
C14: Cost of goods sold | E14: 0 | F14: 0 | G14: 0 | H14: 0 | I14: 0 | J14: 0 | K14: 0 | L14: 0 | M14: 0 | N14: 0 | O14: 0 | P14: 0 | Q14: 0 | R14: 0 | S14: 0 | T14: 0 | U14: 0 | V14: 0 | W14: 0 | X14: 0 | Y14: 0 | Z14: 0 | AA14: 0 | AB14: 0 | AC14: 0 | AD14: 0 | AE14: 0 | AF14: 0 | AG14: 0 | AH14: 0 | AI14: 0 | AK14: =SUM(E14:P14) -> 0 | AL14: =SUM(Q14:AB14) -> 0 | AM14: =SUM(X14:AI14) -> 0 | AO14: =IFERROR(AK14/AK$10%,0) -> 0 | AP14: =IFERROR(AL14/AL$10%,0) -> 0 | AQ14: =IFERROR(AM14/AM$10%,0) -> 0
C15: Gross profit | E15: =E10-E14 -> 193.127 | F15: =F10-F14 -> 429.4435 | G15: =G10-G14 -> 731.815 | H15: =H10-H14 -> 430.355 | I15: =I10-I14 -> 623.429 | J15: =J10-J14 -> 480.831 | K15: =K10-K14 -> 688.468 | L15: =L10-L14 -> 1267.3995 | ... AI15: =AI10-AI14 -> 423.188 | AK15: =AK10-AK14 -> 7647.4216 | AL15: =AL10-AL14 -> 6778.7512 | AM15: =AM10-AM14 -> 7343.4143 | AO15: =IFERROR(AK15/AK$10%,0) -> 100 | AP15: =IFERROR(AL15/AL$10%,0) -> 100 | AQ15: =IFERROR(AM15/AM$10%,0) -> 100
C17: Payroll and benefits | E17: =_xlfn.XLOOKUP($C17,'PL1'!$C:$C,'PL1'!E:E)-SUMIFS(ADJ!G:G,ADJ!$E:$E,'RPL1'!$C17) -> 298.69046 | F17: =_xlfn.XLOOKUP($C17,'PL1'!$C:$C,'PL1'!F:F)-SUMIFS(ADJ!H:H,ADJ!$E:$E,'RPL1'!$C17) -> 298.48344 | G17: =_xlfn.XLOOKUP($C17,'PL1'!$C:$C,'PL1'!G:G)-SUMIFS(ADJ!I:I,ADJ!$E:$E,'RPL1'!$C17) -> 284.31467 | H17: =_xlfn.XLOOKUP($C17,'PL1'!$C:$C,'PL1'!H:H)-SUMIFS(ADJ!J:J,ADJ!$E:$E,'RPL1'!$C17) -> 276.68906 | I17: =_xlfn.XLOOKUP($C17,'PL1'!$C:$C,'PL1'!I:I)-SUMIFS(ADJ!K:K,ADJ!$E:$E,'RPL1'!$C17) -> 268.97223 | J17: =_xlfn.XLOOKUP($C17,'PL1'!$C:$C,'PL1'!J:J)-SUMIFS(ADJ!L:L,ADJ!$E:$E,'RPL1'!$C17) -> 266.65804 | K17: =_xlfn.XLOOKUP($C17,'PL1'!$C:$C,'PL1'!K:K)-SUMIFS(ADJ!M:M,ADJ!$E:$E,'RPL1'!$C17) -> 268.30101 | L17: =_xlfn.XLOOKUP($C17,'PL1'!$C:$C,'PL1'!L:L)-SUMIFS(ADJ!N:N,ADJ!$E:$E,'RPL1'!$C17) -> 266.73588 | M17: =_xlfn.XLOOKUP($C17,'PL1'!$C:$C,'PL1'!M:M)-SUMIFS(ADJ!O:O,ADJ!$E:$E,'RPL1'!$C17) -> 265.08172 | N17: =_xlfn.XLOOKUP($C17,'PL1'!$C:$C,'PL1'!N:N)-SUMIFS(ADJ!P:P,ADJ!$E:$E,'RPL1'!$C17) -> 281.37695 | O17: =_xlfn.XLOOKUP($C17,'PL1'!$C:$C,'PL1'!O:O)-SUMIFS(ADJ!Q:Q,ADJ!$E:$E,'RPL1'!$C17) -> 275.32041 | P17: =_xlfn.XLOOKUP($C17,'PL1'!$C:$C,'PL1'!P:P)-SUMIFS(ADJ!R:R,ADJ!$E:$E,'RPL1'!$C17) -> 375.49239 | Q17: =_xlfn.XLOOKUP($C17,'PL1'!$C:$C,'PL1'!Q:Q)-SUMIFS(ADJ!S:S,ADJ!$E:$E,'RPL1'!$C17) -> 271.91109 | R17: =_xlfn.XLOOKUP($C17,'PL1'!$C:$C,'PL1'!R:R)-SUMIFS(ADJ!T:T,ADJ!$E:$E,'RPL1'!$C17) -> 271.61953 | S17: =_xlfn.XLOOKUP($C17,'PL1'!$C:$C,'PL1'!S:S)-SUMIFS(ADJ!U:U,ADJ!$E:$E,'RPL1'!$C17) -> 293.90775 | T17: =_xlfn.XLOOKUP($C17,'PL1'!$C:$C,'PL1'!T:T)-SUMIFS(ADJ!V:V,ADJ!$E:$E,'RPL1'!$C17) -> 301.94597 | U17: =_xlfn.XLOOKUP($C17,'PL1'!$C:$C,'PL1'!U:U)-SUMIFS(ADJ!W:W,ADJ!$E:$E,'RPL1'!$C17) -> 296.50785 | V17: =_xlfn.XLOOKUP($C17,'PL1'!$C:$C,'PL1'!V:V)-SUMIFS(ADJ!X:X,ADJ!$E:$E,'RPL1'!$C17) -> 292.17041 | W17: =_xlfn.XLOOKUP($C17,'PL1'!$C:$C,'PL1'!W:W)-SUMIFS(ADJ!Y:Y,ADJ!$E:$E,'RPL1'!$C17) -> 290.4759 | X17: =_xlfn.XLOOKUP($C17,'PL1'!$C:$C,'PL1'!X:X)-SUMIFS(ADJ!Z:Z,ADJ!$E:$E,'RPL1'!$C17) -> 291.3456 | Y17: =_xlfn.XLOOKUP($C17,'PL1'!$C:$C,'PL1'!Y:Y)-SUMIFS(ADJ!AA:AA,ADJ!$E:$E,'RPL1'!$C17) -> 287.43833 | Z17: =_xlfn.XLOOKUP($C17,'PL1'!$C:$C,'PL1'!Z:Z)-SUMIFS(ADJ!AB:AB,ADJ!$E:$E,'RPL1'!$C17) -> -219.3722 | AA17: =_xlfn.XLOOKUP($C17,'PL1'!$C:$C,'PL1'!AA:AA)-SUMIFS(ADJ!AC:AC,ADJ!$E:$E,'RPL1'!$C17) -> 244.77622 | AB17: =_xlfn.XLOOKUP($C17,'PL1'!$C:$C,'PL1'!AB:AB)-SUMIFS(ADJ!AD:AD,ADJ!$E:$E,'RPL1'!$C17) -> 152.51136 | AC17: =_xlfn.XLOOKUP($C17,'PL1'!$C:$C,'PL1'!AC:AC)-SUMIFS(ADJ!AE:AE,ADJ!$E:$E,'RPL1'!$C17) -> 232.1368 | AD17: =_xlfn.XLOOKUP($C17,'PL1'!$C:$C,'PL1'!AD:AD)-SUMIFS(ADJ!AF:AF,ADJ!$E:$E,'RPL1'!$C17) -> 333.07219 | AE17: =_xlfn.XLOOKUP($C17,'PL1'!$C:$C,'PL1'!AE:AE)-SUMIFS(ADJ!AG:AG,ADJ!$E:$E,'RPL1'!$C17) -> 281.43373 | AF17: =_xlfn.XLOOKUP($C17,'PL1'!$C:$C,'PL1'!AF:AF)-SUMIFS(ADJ!AH:AH,ADJ!$E:$E,'RPL1'!$C17) -> 281.47455 | AG17: =_xlfn.XLOOKUP($C17,'PL1'!$C:$C,'PL1'!AG:AG)-SUMIFS(ADJ!AI:AI,ADJ!$E:$E,'RPL1'!$C17) -> 281.31166 | AH17: =_xlfn.XLOOKUP($C17,'PL1'!$C:$C,'PL1'!AH:AH)-SUMIFS(ADJ!AJ:AJ,ADJ!$E:$E,'RPL1'!$C17) -> 280.26423 | AI17: =_xlfn.XLOOKUP($C17,'PL1'!$C:$C,'PL1'!AI:AI)-SUMIFS(ADJ!AK:AK,ADJ!$E:$E,'RPL1'!$C17) -> 287.17413 | AK17: =SUM(E17:P17) -> 3426.1163 | AL17: =SUM(Q17:AB17) -> 2775.2378 | AM17: =SUM(X17:AI17) -> 2733.5666 | AO17: =IFERROR(AK17/AK$10%,0) -> 44.800933 | AP17: =IFERROR(AL17/AL$10%,0) -> 40.940252 | AQ17: =IFERROR(AM17/AM$10%,0) -> 37.224736
C18: Subcontractor expense | E18: =_xlfn.XLOOKUP($C18,'PL1'!$C:$C,'PL1'!E:E)-SUMIFS(ADJ!G:G,ADJ!$E:$E,'RPL1'!$C18) -> 137.43364 | F18: =_xlfn.XLOOKUP($C18,'PL1'!$C:$C,'PL1'!F:F)-SUMIFS(ADJ!H:H,ADJ!$E:$E,'RPL1'!$C18) -> 193.54791 | G18: =_xlfn.XLOOKUP($C18,'PL1'!$C:$C,'PL1'!G:G)-SUMIFS(ADJ!I:I,ADJ!$E:$E,'RPL1'!$C18) -> 224.92213 | H18: =_xlfn.XLOOKUP($C18,'PL1'!$C:$C,'PL1'!H:H)-SUMIFS(ADJ!J:J,ADJ!$E:$E,'RPL1'!$C18) -> 125.26819 | I18: =_xlfn.XLOOKUP($C18,'PL1'!$C:$C,'PL1'!I:I)-SUMIFS(ADJ!K:K,ADJ!$E:$E,'RPL1'!$C18) -> 176.70462 | J18: =_xlfn.XLOOKUP($C18,'PL1'!$C:$C,'PL1'!J:J)-SUMIFS(ADJ!L:L,ADJ!$E:$E,'RPL1'!$C18) -> 178.79571 | K18: =_xlfn.XLOOKUP($C18,'PL1'!$C:$C,'PL1'!K:K)-SUMIFS(ADJ!M:M,ADJ!$E:$E,'RPL1'!$C18) -> 270.18698 | L18: =_xlfn.XLOOKUP($C18,'PL1'!$C:$C,'PL1'!L:L)-SUMIFS(ADJ!N:N,ADJ!$E:$E,'RPL1'!$C18) -> 287.13071 | M18: =_xlfn.XLOOKUP($C18,'PL1'!$C:$C,'PL1'!M:M)-SUMIFS(ADJ!O:O,ADJ!$E:$E,'RPL1'!$C18) -> 147.99318 | N18: =_xlfn.XLOOKUP($C18,'PL1'!$C:$C,'PL1'!N:N)-SUMIFS(ADJ!P:P,ADJ!$E:$E,'RPL1'!$C18) -> 165.18797 | O18: =_xlfn.XLOOKUP($C18,'PL1'!$C:$C,'PL1'!O:O)-SUMIFS(ADJ!Q:Q,ADJ!$E:$E,'RPL1'!$C18) -> 337.44583 | P18: =_xlfn.XLOOKUP($C18,'PL1'!$C:$C,'PL1'!P:P)-SUMIFS(ADJ!R:R,ADJ!$E:$E,'RPL1'!$C18) -> 319.66356 | Q18: =_xlfn.XLOOKUP($C18,'PL1'!$C:$C,'PL1'!Q:Q)-SUMIFS(ADJ!S:S,ADJ!$E:$E,'RPL1'!$C18) -> 168.82725 | R18: =_xlfn.XLOOKUP($C18,'PL1'!$C:$C,'PL1'!R:R)-SUMIFS(ADJ!T:T,ADJ!$E:$E,'RPL1'!$C18) -> 120.0455 | S18: =_xlfn.XLOOKUP($C18,'PL1'!$C:$C,'PL1'!S:S)-SUMIFS(ADJ!U:U,ADJ!$E:$E,'RPL1'!$C18) -> 172.70988 | T18: =_xlfn.XLOOKUP($C18,'PL1'!$C:$C,'PL1'!T:T)-SUMIFS(ADJ!V:V,ADJ!$E:$E,'RPL1'!$C18) -> 148.45572 | U18: =_xlfn.XLOOKUP($C18,'PL1'!$C:$C,'PL1'!U:U)-SUMIFS(ADJ!W:W,ADJ!$E:$E,'RPL1'!$C18) -> 179.57611 | V18: =_xlfn.XLOOKUP($C18,'PL1'!$C:$C,'PL1'!V:V)-SUMIFS(ADJ!X:X,ADJ!$E:$E,'RPL1'!$C18) -> 152.01988 | W18: =_xlfn.XLOOKUP($C18,'PL1'!$C:$C,'PL1'!W:W)-SUMIFS(ADJ!Y:Y,ADJ!$E:$E,'RPL1'!$C18) -> 223.98869 | X18: =_xlfn.XLOOKUP($C18,'PL1'!$C:$C,'PL1'!X:X)-SUMIFS(ADJ!Z:Z,ADJ!$E:$E,'RPL1'!$C18) -> 213.07865 | Y18: =_xlfn.XLOOKUP($C18,'PL1'!$C:$C,'PL1'!Y:Y)-SUMIFS(ADJ!AA:AA,ADJ!$E:$E,'RPL1'!$C18) -> 202.70499 | Z18: =_xlfn.XLOOKUP($C18,'PL1'!$C:$C,'PL1'!Z:Z)-SUMIFS(ADJ!AB:AB,ADJ!$E:$E,'RPL1'!$C18) -> 285.08553 | AA18: =_xlfn.XLOOKUP($C18,'PL1'!$C:$C,'PL1'!AA:AA)-SUMIFS(ADJ!AC:AC,ADJ!$E:$E,'RPL1'!$C18) -> 114.44835 | AB18: =_xlfn.XLOOKUP($C18,'PL1'!$C:$C,'PL1'!AB:AB)-SUMIFS(ADJ!AD:AD,ADJ!$E:$E,'RPL1'!$C18) -> 188.95704 | AC18: =_xlfn.XLOOKUP($C18,'PL1'!$C:$C,'PL1'!AC:AC)-SUMIFS(ADJ!AE:AE,ADJ!$E:$E,'RPL1'!$C18) -> 199.86529 | AD18: =_xlfn.XLOOKUP($C18,'PL1'!$C:$C,'PL1'!AD:AD)-SUMIFS(ADJ!AF:AF,ADJ!$E:$E,'RPL1'!$C18) -> 178.72288 | AE18: =_xlfn.XLOOKUP($C18,'PL1'!$C:$C,'PL1'!AE:AE)-SUMIFS(ADJ!AG:AG,ADJ!$E:$E,'RPL1'!$C18) -> 266.13393 | AF18: =_xlfn.XLOOKUP($C18,'PL1'!$C:$C,'PL1'!AF:AF)-SUMIFS(ADJ!AH:AH,ADJ!$E:$E,'RPL1'!$C18) -> 115.1346 | AG18: =_xlfn.XLOOKUP($C18,'PL1'!$C:$C,'PL1'!AG:AG)-SUMIFS(ADJ!AI:AI,ADJ!$E:$E,'RPL1'!$C18) -> 207.44051 | AH18: =_xlfn.XLOOKUP($C18,'PL1'!$C:$C,'PL1'!AH:AH)-SUMIFS(ADJ!AJ:AJ,ADJ!$E:$E,'RPL1'!$C18) -> 184.72747 | AI18: =_xlfn.XLOOKUP($C18,'PL1'!$C:$C,'PL1'!AI:AI)-SUMIFS(ADJ!AK:AK,ADJ!$E:$E,'RPL1'!$C18) -> 191.75563 | AK18: =SUM(E18:P18) -> 2564.2804 | AL18: =SUM(Q18:AB18) -> 2169.8976 | AM18: =SUM(X18:AI18) -> 2348.0549 | AO18: =IFERROR(AK18/AK$10%,0) -> 33.531307 | AP18: =IFERROR(AL18/AL$10%,0) -> 32.010285 | AQ18: =IFERROR(AM18/AM$10%,0) -> 31.974975
C19: Insurance expenses | E19: =_xlfn.XLOOKUP($C19,'PL1'!$C:$C,'PL1'!E:E)-SUMIFS(ADJ!G:G,ADJ!$E:$E,'RPL1'!$C19) -> 38.03793 | F19: =_xlfn.XLOOKUP($C19,'PL1'!$C:$C,'PL1'!F:F)-SUMIFS(ADJ!H:H,ADJ!$E:$E,'RPL1'!$C19) -> 29.35666 | G19: =_xlfn.XLOOKUP($C19,'PL1'!$C:$C,'PL1'!G:G)-SUMIFS(ADJ!I:I,ADJ!$E:$E,'RPL1'!$C19) -> 34.11322 | H19: =_xlfn.XLOOKUP($C19,'PL1'!$C:$C,'PL1'!H:H)-SUMIFS(ADJ!J:J,ADJ!$E:$E,'RPL1'!$C19) -> 41.28279 | I19: =_xlfn.XLOOKUP($C19,'PL1'!$C:$C,'PL1'!I:I)-SUMIFS(ADJ!K:K,ADJ!$E:$E,'RPL1'!$C19) -> 58.56752 | J19: =_xlfn.XLOOKUP($C19,'PL1'!$C:$C,'PL1'!J:J)-SUMIFS(ADJ!L:L,ADJ!$E:$E,'RPL1'!$C19) -> 39.98386 | K19: =_xlfn.XLOOKUP($C19,'PL1'!$C:$C,'PL1'!K:K)-SUMIFS(ADJ!M:M,ADJ!$E:$E,'RPL1'!$C19) -> 22.85944 | L19: =_xlfn.XLOOKUP($C19,'PL1'!$C:$C,'PL1'!L:L)-SUMIFS(ADJ!N:N,ADJ!$E:$E,'RPL1'!$C19) -> 25.82988 | M19: =_xlfn.XLOOKUP($C19,'PL1'!$C:$C,'PL1'!M:M)-SUMIFS(ADJ!O:O,ADJ!$E:$E,'RPL1'!$C19) -> 29.66964 | N19: =_xlfn.XLOOKUP($C19,'PL1'!$C:$C,'PL1'!N:N)-SUMIFS(ADJ!P:P,ADJ!$E:$E,'RPL1'!$C19) -> 23.20154 | O19: =_xlfn.XLOOKUP($C19,'PL1'!$C:$C,'PL1'!O:O)-SUMIFS(ADJ!Q:Q,ADJ!$E:$E,'RPL1'!$C19) -> 29.62384 | P19: =_xlfn.XLOOKUP($C19,'PL1'!$C:$C,'PL1'!P:P)-SUMIFS(ADJ!R:R,ADJ!$E:$E,'RPL1'!$C19) -> -98.05435 | Q19: =_xlfn.XLOOKUP($C19,'PL1'!$C:$C,'PL1'!Q:Q)-SUMIFS(ADJ!S:S,ADJ!$E:$E,'RPL1'!$C19) -> 30.08207 | R19: =_xlfn.XLOOKUP($C19,'PL1'!$C:$C,'PL1'!R:R)-SUMIFS(ADJ!T:T,ADJ!$E:$E,'RPL1'!$C19) -> 28.76204 | S19: =_xlfn.XLOOKUP($C19,'PL1'!$C:$C,'PL1'!S:S)-SUMIFS(ADJ!U:U,ADJ!$E:$E,'RPL1'!$C19) -> 29.71568 | T19: =_xlfn.XLOOKUP($C19,'PL1'!$C:$C,'PL1'!T:T)-SUMIFS(ADJ!V:V,ADJ!$E:$E,'RPL1'!$C19) -> 21.52508 | U19: =_xlfn.XLOOKUP($C19,'PL1'!$C:$C,'PL1'!U:U)-SUMIFS(ADJ!W:W,ADJ!$E:$E,'RPL1'!$C19) -> 35.72831 | V19: =_xlfn.XLOOKUP($C19,'PL1'!$C:$C,'PL1'!V:V)-SUMIFS(ADJ!X:X,ADJ!$E:$E,'RPL1'!$C19) -> 2.27021 | W19: =_xlfn.XLOOKUP($C19,'PL1'!$C:$C,'PL1'!W:W)-SUMIFS(ADJ!Y:Y,ADJ!$E:$E,'RPL1'!$C19) -> 1.37946 | X19: =_xlfn.XLOOKUP($C19,'PL1'!$C:$C,'PL1'!X:X)-SUMIFS(ADJ!Z:Z,ADJ!$E:$E,'RPL1'!$C19) -> 1.37946 | Y19: =_xlfn.XLOOKUP($C19,'PL1'!$C:$C,'PL1'!Y:Y)-SUMIFS(ADJ!AA:AA,ADJ!$E:$E,'RPL1'!$C19) -> 2.27021 | Z19: =_xlfn.XLOOKUP($C19,'PL1'!$C:$C,'PL1'!Z:Z)-SUMIFS(ADJ!AB:AB,ADJ!$E:$E,'RPL1'!$C19) -> 5.12946 | AA19: =_xlfn.XLOOKUP($C19,'PL1'!$C:$C,'PL1'!AA:AA)-SUMIFS(ADJ!AC:AC,ADJ!$E:$E,'RPL1'!$C19) -> 3.87946 | AB19: =_xlfn.XLOOKUP($C19,'PL1'!$C:$C,'PL1'!AB:AB)-SUMIFS(ADJ!AD:AD,ADJ!$E:$E,'RPL1'!$C19) -> 161.87645 | AC19: =_xlfn.XLOOKUP($C19,'PL1'!$C:$C,'PL1'!AC:AC)-SUMIFS(ADJ!AE:AE,ADJ!$E:$E,'RPL1'!$C19) -> 1.37946 | AD19: =_xlfn.XLOOKUP($C19,'PL1'!$C:$C,'PL1'!AD:AD)-SUMIFS(ADJ!AF:AF,ADJ!$E:$E,'RPL1'!$C19) -> 1.37946 | AE19: =_xlfn.XLOOKUP($C19,'PL1'!$C:$C,'PL1'!AE:AE)-SUMIFS(ADJ!AG:AG,ADJ!$E:$E,'RPL1'!$C19) -> 1.37946 | AF19: =_xlfn.XLOOKUP($C19,'PL1'!$C:$C,'PL1'!AF:AF)-SUMIFS(ADJ!AH:AH,ADJ!$E:$E,'RPL1'!$C19) -> 19.41746 | AG19: =_xlfn.XLOOKUP($C19,'PL1'!$C:$C,'PL1'!AG:AG)-SUMIFS(ADJ!AI:AI,ADJ!$E:$E,'RPL1'!$C19) -> 1.37946 | AH19: =_xlfn.XLOOKUP($C19,'PL1'!$C:$C,'PL1'!AH:AH)-SUMIFS(ADJ!AJ:AJ,ADJ!$E:$E,'RPL1'!$C19) -> 32.10602 | AI19: =_xlfn.XLOOKUP($C19,'PL1'!$C:$C,'PL1'!AI:AI)-SUMIFS(ADJ!AK:AK,ADJ!$E:$E,'RPL1'!$C19) -> 4.77156 | AK19: =SUM(E19:P19) -> 274.47197 | AL19: =SUM(Q19:AB19) -> 323.99789 | AM19: =SUM(X19:AI19) -> 236.34792 | AO19: =IFERROR(AK19/AK$10%,0) -> 3.5890786 | AP19: =IFERROR(AL19/AL$10%,0) -> 4.7796103 | AQ19: =IFERROR(AM19/AM$10%,0) -> 3.2185018
C20: Professional fees | E20: =_xlfn.XLOOKUP($C20,'PL1'!$C:$C,'PL1'!E:E)-SUMIFS(ADJ!G:G,ADJ!$E:$E,'RPL1'!$C20) -> 8.555 | F20: =_xlfn.XLOOKUP($C20,'PL1'!$C:$C,'PL1'!F:F)-SUMIFS(ADJ!H:H,ADJ!$E:$E,'RPL1'!$C20) -> 7.6875 | G20: =_xlfn.XLOOKUP($C20,'PL1'!$C:$C,'PL1'!G:G)-SUMIFS(ADJ!I:I,ADJ!$E:$E,'RPL1'!$C20) -> 5.6 | H20: =_xlfn.XLOOKUP($C20,'PL1'!$C:$C,'PL1'!H:H)-SUMIFS(ADJ!J:J,ADJ!$E:$E,'RPL1'!$C20) -> 11.74 | I20: =_xlfn.XLOOKUP($C20,'PL1'!$C:$C,'PL1'!I:I)-SUMIFS(ADJ!K:K,ADJ!$E:$E,'RPL1'!$C20) -> 0 | J20: =_xlfn.XLOOKUP($C20,'PL1'!$C:$C,'PL1'!J:J)-SUMIFS(ADJ!L:L,ADJ!$E:$E,'RPL1'!$C20) -> 15.34 | K20: =_xlfn.XLOOKUP($C20,'PL1'!$C:$C,'PL1'!K:K)-SUMIFS(ADJ!M:M,ADJ!$E:$E,'RPL1'!$C20) -> 9.9475 | L20: =_xlfn.XLOOKUP($C20,'PL1'!$C:$C,'PL1'!L:L)-SUMIFS(ADJ!N:N,ADJ!$E:$E,'RPL1'!$C20) -> 8 | M20: =_xlfn.XLOOKUP($C20,'PL1'!$C:$C,'PL1'!M:M)-SUMIFS(ADJ!O:O,ADJ!$E:$E,'RPL1'!$C20) -> 8.565 | N20: =_xlfn.XLOOKUP($C20,'PL1'!$C:$C,'PL1'!N:N)-SUMIFS(ADJ!P:P,ADJ!$E:$E,'RPL1'!$C20) -> 8 | O20: =_xlfn.XLOOKUP($C20,'PL1'!$C:$C,'PL1'!O:O)-SUMIFS(ADJ!Q:Q,ADJ!$E:$E,'RPL1'!$C20) -> 11.02 | P20: =_xlfn.XLOOKUP($C20,'PL1'!$C:$C,'PL1'!P:P)-SUMIFS(ADJ!R:R,ADJ!$E:$E,'RPL1'!$C20) -> 8.895 | Q20: =_xlfn.XLOOKUP($C20,'PL1'!$C:$C,'PL1'!Q:Q)-SUMIFS(ADJ!S:S,ADJ!$E:$E,'RPL1'!$C20) -> 9.63307 | R20: =_xlfn.XLOOKUP($C20,'PL1'!$C:$C,'PL1'!R:R)-SUMIFS(ADJ!T:T,ADJ!$E:$E,'RPL1'!$C20) -> 8 | S20: =_xlfn.XLOOKUP($C20,'PL1'!$C:$C,'PL1'!S:S)-SUMIFS(ADJ!U:U,ADJ!$E:$E,'RPL1'!$C20) -> 14.865 | T20: =_xlfn.XLOOKUP($C20,'PL1'!$C:$C,'PL1'!T:T)-SUMIFS(ADJ!V:V,ADJ!$E:$E,'RPL1'!$C20) -> 18.3315 | U20: =_xlfn.XLOOKUP($C20,'PL1'!$C:$C,'PL1'!U:U)-SUMIFS(ADJ!W:W,ADJ!$E:$E,'RPL1'!$C20) -> 0 | V20: =_xlfn.XLOOKUP($C20,'PL1'!$C:$C,'PL1'!V:V)-SUMIFS(ADJ!X:X,ADJ!$E:$E,'RPL1'!$C20) -> 10.4 | W20: =_xlfn.XLOOKUP($C20,'PL1'!$C:$C,'PL1'!W:W)-SUMIFS(ADJ!Y:Y,ADJ!$E:$E,'RPL1'!$C20) -> 11.395 | X20: =_xlfn.XLOOKUP($C20,'PL1'!$C:$C,'PL1'!X:X)-SUMIFS(ADJ!Z:Z,ADJ!$E:$E,'RPL1'!$C20) -> 15.605 | Y20: =_xlfn.XLOOKUP($C20,'PL1'!$C:$C,'PL1'!Y:Y)-SUMIFS(ADJ!AA:AA,ADJ!$E:$E,'RPL1'!$C20) -> 15.5445 | Z20: =_xlfn.XLOOKUP($C20,'PL1'!$C:$C,'PL1'!Z:Z)-SUMIFS(ADJ!AB:AB,ADJ!$E:$E,'RPL1'!$C20) -> 8.75 | AA20: =_xlfn.XLOOKUP($C20,'PL1'!$C:$C,'PL1'!AA:AA)-SUMIFS(ADJ!AC:AC,ADJ!$E:$E,'RPL1'!$C20) -> 30.472 | AB20: =_xlfn.XLOOKUP($C20,'PL1'!$C:$C,'PL1'!AB:AB)-SUMIFS(ADJ!AD:AD,ADJ!$E:$E,'RPL1'!$C20) -> 10.5485 | AC20: =_xlfn.XLOOKUP($C20,'PL1'!$C:$C,'PL1'!AC:AC)-SUMIFS(ADJ!AE:AE,ADJ!$E:$E,'RPL1'!$C20) -> 11.5333 | AD20: =_xlfn.XLOOKUP($C20,'PL1'!$C:$C,'PL1'!AD:AD)-SUMIFS(ADJ!AF:AF,ADJ!$E:$E,'RPL1'!$C20) -> 11.735 | AE20: =_xlfn.XLOOKUP($C20,'PL1'!$C:$C,'PL1'!AE:AE)-SUMIFS(ADJ!AG:AG,ADJ!$E:$E,'RPL1'!$C20) -> 8.2 | AF20: =_xlfn.XLOOKUP($C20,'PL1'!$C:$C,'PL1'!AF:AF)-SUMIFS(ADJ!AH:AH,ADJ!$E:$E,'RPL1'!$C20) -> 18.68 | AG20: =_xlfn.XLOOKUP($C20,'PL1'!$C:$C,'PL1'!AG:AG)-SUMIFS(ADJ!AI:AI,ADJ!$E:$E,'RPL1'!$C20) -> 8 | AH20: =_xlfn.XLOOKUP($C20,'PL1'!$C:$C,'PL1'!AH:AH)-SUMIFS(ADJ!AJ:AJ,ADJ!$E:$E,'RPL1'!$C20) -> 16.975 | AI20: =_xlfn.XLOOKUP($C20,'PL1'!$C:$C,'PL1'!AI:AI)-SUMIFS(ADJ!AK:AK,ADJ!$E:$E,'RPL1'!$C20) -> 30.6465 | AK20: =SUM(E20:P20) -> 103.35 | AL20: =SUM(Q20:AB20) -> 153.54457 | AM20: =SUM(X20:AI20) -> 186.6898 | AO20: =IFERROR(AK20/AK$10%,0) -> 1.3514359 | AP20: =IFERROR(AL20/AL$10%,0) -> 2.2650864 | AQ20: =IFERROR(AM20/AM$10%,0) -> 2.5422752
C21: Other operating expenses | E21: =_xlfn.XLOOKUP($C21,'PL1'!$C:$C,'PL1'!E:E)-SUMIFS(ADJ!G:G,ADJ!$E:$E,'RPL1'!$C21) -> 17.17885 | F21: =_xlfn.XLOOKUP($C21,'PL1'!$C:$C,'PL1'!F:F)-SUMIFS(ADJ!H:H,ADJ!$E:$E,'RPL1'!$C21) -> 3.84806 | G21: =_xlfn.XLOOKUP($C21,'PL1'!$C:$C,'PL1'!G:G)-SUMIFS(ADJ!I:I,ADJ!$E:$E,'RPL1'!$C21) -> 14.08236 | H21: =_xlfn.XLOOKUP($C21,'PL1'!$C:$C,'PL1'!H:H)-SUMIFS(ADJ!J:J,ADJ!$E:$E,'RPL1'!$C21) -> 9.39415 | I21: =_xlfn.XLOOKUP($C21,'PL1'!$C:$C,'PL1'!I:I)-SUMIFS(ADJ!K:K,ADJ!$E:$E,'RPL1'!$C21) -> 8.24328 | J21: =_xlfn.XLOOKUP($C21,'PL1'!$C:$C,'PL1'!J:J)-SUMIFS(ADJ!L:L,ADJ!$E:$E,'RPL1'!$C21) -> 15.33891 | K21: =_xlfn.XLOOKUP($C21,'PL1'!$C:$C,'PL1'!K:K)-SUMIFS(ADJ!M:M,ADJ!$E:$E,'RPL1'!$C21) -> 8.81472 | L21: =_xlfn.XLOOKUP($C21,'PL1'!$C:$C,'PL1'!L:L)-SUMIFS(ADJ!N:N,ADJ!$E:$E,'RPL1'!$C21) -> 4.33986 | M21: =_xlfn.XLOOKUP($C21,'PL1'!$C:$C,'PL1'!M:M)-SUMIFS(ADJ!O:O,ADJ!$E:$E,'RPL1'!$C21) -> 8.56791 | N21: =_xlfn.XLOOKUP($C21,'PL1'!$C:$C,'PL1'!N:N)-SUMIFS(ADJ!P:P,ADJ!$E:$E,'RPL1'!$C21) -> 6.50756 | O21: =_xlfn.XLOOKUP($C21,'PL1'!$C:$C,'PL1'!O:O)-SUMIFS(ADJ!Q:Q,ADJ!$E:$E,'RPL1'!$C21) -> 5.84441 | P21: =_xlfn.XLOOKUP($C21,'PL1'!$C:$C,'PL1'!P:P)-SUMIFS(ADJ!R:R,ADJ!$E:$E,'RPL1'!$C21) -> 11.80133 | Q21: =_xlfn.XLOOKUP($C21,'PL1'!$C:$C,'PL1'!Q:Q)-SUMIFS(ADJ!S:S,ADJ!$E:$E,'RPL1'!$C21) -> 14.06012 | R21: =_xlfn.XLOOKUP($C21,'PL1'!$C:$C,'PL1'!R:R)-SUMIFS(ADJ!T:T,ADJ!$E:$E,'RPL1'!$C21) -> 9.06727 | S21: =_xlfn.XLOOKUP($C21,'PL1'!$C:$C,'PL1'!S:S)-SUMIFS(ADJ!U:U,ADJ!$E:$E,'RPL1'!$C21) -> 7.78589 | T21: =_xlfn.XLOOKUP($C21,'PL1'!$C:$C,'PL1'!T:T)-SUMIFS(ADJ!V:V,ADJ!$E:$E,'RPL1'!$C21) -> 4.29555 | U21: =_xlfn.XLOOKUP($C21,'PL1'!$C:$C,'PL1'!U:U)-SUMIFS(ADJ!W:W,ADJ!$E:$E,'RPL1'!$C21) -> 8.93703 | V21: =_xlfn.XLOOKUP($C21,'PL1'!$C:$C,'PL1'!V:V)-SUMIFS(ADJ!X:X,ADJ!$E:$E,'RPL1'!$C21) -> 11.02111 | W21: =_xlfn.XLOOKUP($C21,'PL1'!$C:$C,'PL1'!W:W)-SUMIFS(ADJ!Y:Y,ADJ!$E:$E,'RPL1'!$C21) -> 6.69698 | X21: =_xlfn.XLOOKUP($C21,'PL1'!$C:$C,'PL1'!X:X)-SUMIFS(ADJ!Z:Z,ADJ!$E:$E,'RPL1'!$C21) -> 4.26963 | Y21: =_xlfn.XLOOKUP($C21,'PL1'!$C:$C,'PL1'!Y:Y)-SUMIFS(ADJ!AA:AA,ADJ!$E:$E,'RPL1'!$C21) -> 9.7357 | Z21: =_xlfn.XLOOKUP($C21,'PL1'!$C:$C,'PL1'!Z:Z)-SUMIFS(ADJ!AB:AB,ADJ!$E:$E,'RPL1'!$C21) -> 7.30678 | AA21: =_xlfn.XLOOKUP($C21,'PL1'!$C:$C,'PL1'!AA:AA)-SUMIFS(ADJ!AC:AC,ADJ!$E:$E,'RPL1'!$C21) -> 8.49059 | AB21: =_xlfn.XLOOKUP($C21,'PL1'!$C:$C,'PL1'!AB:AB)-SUMIFS(ADJ!AD:AD,ADJ!$E:$E,'RPL1'!$C21) -> 11.91501 | AC21: =_xlfn.XLOOKUP($C21,'PL1'!$C:$C,'PL1'!AC:AC)-SUMIFS(ADJ!AE:AE,ADJ!$E:$E,'RPL1'!$C21) -> 6.7009 | AD21: =_xlfn.XLOOKUP($C21,'PL1'!$C:$C,'PL1'!AD:AD)-SUMIFS(ADJ!AF:AF,ADJ!$E:$E,'RPL1'!$C21) -> 12.54305 | AE21: =_xlfn.XLOOKUP($C21,'PL1'!$C:$C,'PL1'!AE:AE)-SUMIFS(ADJ!AG:AG,ADJ!$E:$E,'RPL1'!$C21) -> 8.95995 | AF21: =_xlfn.XLOOKUP($C21,'PL1'!$C:$C,'PL1'!AF:AF)-SUMIFS(ADJ!AH:AH,ADJ!$E:$E,'RPL1'!$C21) -> 10.2829 | AG21: =_xlfn.XLOOKUP($C21,'PL1'!$C:$C,'PL1'!AG:AG)-SUMIFS(ADJ!AI:AI,ADJ!$E:$E,'RPL1'!$C21) -> 9.99205 | AH21: =_xlfn.XLOOKUP($C21,'PL1'!$C:$C,'PL1'!AH:AH)-SUMIFS(ADJ!AJ:AJ,ADJ!$E:$E,'RPL1'!$C21) -> 10.18761 | AI21: =_xlfn.XLOOKUP($C21,'PL1'!$C:$C,'PL1'!AI:AI)-SUMIFS(ADJ!AK:AK,ADJ!$E:$E,'RPL1'!$C21) -> 10.79615 | AK21: =SUM(E21:P21) -> 113.9614 | AL21: =SUM(Q21:AB21) -> 103.58166 | AM21: =SUM(X21:AI21) -> 111.18032 | AO21: =IFERROR(AK21/AK$10%,0) -> 1.4901938 | AP21: =IFERROR(AL21/AL$10%,0) -> 1.5280346 | AQ21: =IFERROR(AM21/AM$10%,0) -> 1.514014
C22: Travel, meals, and entertainment | E22: =_xlfn.XLOOKUP($C22,'PL1'!$C:$C,'PL1'!E:E)-SUMIFS(ADJ!G:G,ADJ!$E:$E,'RPL1'!$C22) -> 1.7244 | F22: =_xlfn.XLOOKUP($C22,'PL1'!$C:$C,'PL1'!F:F)-SUMIFS(ADJ!H:H,ADJ!$E:$E,'RPL1'!$C22) -> 3.10804 | G22: =_xlfn.XLOOKUP($C22,'PL1'!$C:$C,'PL1'!G:G)-SUMIFS(ADJ!I:I,ADJ!$E:$E,'RPL1'!$C22) -> 4.45087 | H22: =_xlfn.XLOOKUP($C22,'PL1'!$C:$C,'PL1'!H:H)-SUMIFS(ADJ!J:J,ADJ!$E:$E,'RPL1'!$C22) -> 2.62126 | I22: =_xlfn.XLOOKUP($C22,'PL1'!$C:$C,'PL1'!I:I)-SUMIFS(ADJ!K:K,ADJ!$E:$E,'RPL1'!$C22) -> 2.08538 | J22: =_xlfn.XLOOKUP($C22,'PL1'!$C:$C,'PL1'!J:J)-SUMIFS(ADJ!L:L,ADJ!$E:$E,'RPL1'!$C22) -> 2.66488 | K22: =_xlfn.XLOOKUP($C22,'PL1'!$C:$C,'PL1'!K:K)-SUMIFS(ADJ!M:M,ADJ!$E:$E,'RPL1'!$C22) -> 0.81089 | L22: =_xlfn.XLOOKUP($C22,'PL1'!$C:$C,'PL1'!L:L)-SUMIFS(ADJ!N:N,ADJ!$E:$E,'RPL1'!$C22) -> 0.89428 | M22: =_xlfn.XLOOKUP($C22,'PL1'!$C:$C,'PL1'!M:M)-SUMIFS(ADJ!O:O,ADJ!$E:$E,'RPL1'!$C22) -> 0.164 | N22: =_xlfn.XLOOKUP($C22,'PL1'!$C:$C,'PL1'!N:N)-SUMIFS(ADJ!P:P,ADJ!$E:$E,'RPL1'!$C22) -> 0.12366 | O22: =_xlfn.XLOOKUP($C22,'PL1'!$C:$C,'PL1'!O:O)-SUMIFS(ADJ!Q:Q,ADJ!$E:$E,'RPL1'!$C22) -> 0.5617 | P22: =_xlfn.XLOOKUP($C22,'PL1'!$C:$C,'PL1'!P:P)-SUMIFS(ADJ!R:R,ADJ!$E:$E,'RPL1'!$C22) -> 4.15851 | Q22: =_xlfn.XLOOKUP($C22,'PL1'!$C:$C,'PL1'!Q:Q)-SUMIFS(ADJ!S:S,ADJ!$E:$E,'RPL1'!$C22) -> 4.18701 | R22: =_xlfn.XLOOKUP($C22,'PL1'!$C:$C,'PL1'!R:R)-SUMIFS(ADJ!T:T,ADJ!$E:$E,'RPL1'!$C22) -> 3.82491 | S22: =_xlfn.XLOOKUP($C22,'PL1'!$C:$C,'PL1'!S:S)-SUMIFS(ADJ!U:U,ADJ!$E:$E,'RPL1'!$C22) -> 1.39135 | T22: =_xlfn.XLOOKUP($C22,'PL1'!$C:$C,'PL1'!T:T)-SUMIFS(ADJ!V:V,ADJ!$E:$E,'RPL1'!$C22) -> 0.99821 | U22: =_xlfn.XLOOKUP($C22,'PL1'!$C:$C,'PL1'!U:U)-SUMIFS(ADJ!W:W,ADJ!$E:$E,'RPL1'!$C22) -> 1.34516 | V22: =_xlfn.XLOOKUP($C22,'PL1'!$C:$C,'PL1'!V:V)-SUMIFS(ADJ!X:X,ADJ!$E:$E,'RPL1'!$C22) -> 1.8914 | W22: =_xlfn.XLOOKUP($C22,'PL1'!$C:$C,'PL1'!W:W)-SUMIFS(ADJ!Y:Y,ADJ!$E:$E,'RPL1'!$C22) -> 0.36012 | X22: =_xlfn.XLOOKUP($C22,'PL1'!$C:$C,'PL1'!X:X)-SUMIFS(ADJ!Z:Z,ADJ!$E:$E,'RPL1'!$C22) -> 0 | Y22: =_xlfn.XLOOKUP($C22,'PL1'!$C:$C,'PL1'!Y:Y)-SUMIFS(ADJ!AA:AA,ADJ!$E:$E,'RPL1'!$C22) -> 0.04273 | Z22: =_xlfn.XLOOKUP($C22,'PL1'!$C:$C,'PL1'!Z:Z)-SUMIFS(ADJ!AB:AB,ADJ!$E:$E,'RPL1'!$C22) -> 1.09359 | AA22: =_xlfn.XLOOKUP($C22,'PL1'!$C:$C,'PL1'!AA:AA)-SUMIFS(ADJ!AC:AC,ADJ!$E:$E,'RPL1'!$C22) -> 4.18668 | AB22: =_xlfn.XLOOKUP($C22,'PL1'!$C:$C,'PL1'!AB:AB)-SUMIFS(ADJ!AD:AD,ADJ!$E:$E,'RPL1'!$C22) -> 1.12317 | AC22: =_xlfn.XLOOKUP($C22,'PL1'!$C:$C,'PL1'!AC:AC)-SUMIFS(ADJ!AE:AE,ADJ!$E:$E,'RPL1'!$C22) -> 4.84297 | AD22: =_xlfn.XLOOKUP($C22,'PL1'!$C:$C,'PL1'!AD:AD)-SUMIFS(ADJ!AF:AF,ADJ!$E:$E,'RPL1'!$C22) -> 2.33461 | AE22: =_xlfn.XLOOKUP($C22,'PL1'!$C:$C,'PL1'!AE:AE)-SUMIFS(ADJ!AG:AG,ADJ!$E:$E,'RPL1'!$C22) -> 4.28287 | AF22: =_xlfn.XLOOKUP($C22,'PL1'!$C:$C,'PL1'!AF:AF)-SUMIFS(ADJ!AH:AH,ADJ!$E:$E,'RPL1'!$C22) -> 3.13152 | AG22: =_xlfn.XLOOKUP($C22,'PL1'!$C:$C,'PL1'!AG:AG)-SUMIFS(ADJ!AI:AI,ADJ!$E:$E,'RPL1'!$C22) -> 8.85938 | AH22: =_xlfn.XLOOKUP($C22,'PL1'!$C:$C,'PL1'!AH:AH)-SUMIFS(ADJ!AJ:AJ,ADJ!$E:$E,'RPL1'!$C22) -> 0.91452 | AI22: =_xlfn.XLOOKUP($C22,'PL1'!$C:$C,'PL1'!AI:AI)-SUMIFS(ADJ!AK:AK,ADJ!$E:$E,'RPL1'!$C22) -> 0.25565 | AK22: =SUM(E22:P22) -> 23.36787 | AL22: =SUM(Q22:AB22) -> 20.44433 | AM22: =SUM(X22:AI22) -> 31.06769 | AO22: =IFERROR(AK22/AK$10%,0) -> 0.30556534 | AP22: =IFERROR(AL22/AL$10%,0) -> 0.30159434 | AQ22: =IFERROR(AM22/AM$10%,0) -> 0.42306874
C23: Operating expenses | E23: =SUM(E17:E22) -> 501.62028 | F23: =SUM(F17:F22) -> 536.03161 | G23: =SUM(G17:G22) -> 567.48325 | H23: =SUM(H17:H22) -> 466.99545 | I23: =SUM(I17:I22) -> 514.57303 | J23: =SUM(J17:J22) -> 518.7814 | K23: =SUM(K17:K22) -> 580.92054 | L23: =SUM(L17:L22) -> 592.93061 | ... AI23: =SUM(AI17:AI22) -> 525.39962 | AK23: =SUM(AK17:AK22) -> 6505.5479 | AL23: =SUM(AL17:AL22) -> 5546.7039 | AM23: =SUM(AM17:AM22) -> 5646.9072 | AO23: =IFERROR(AK23/AK$10%,0) -> 85.068514 | AP23: =IFERROR(AL23/AL$10%,0) -> 81.824863 | AQ23: =IFERROR(AM23/AM$10%,0) -> 76.897571
C24: Operating profit | E24: =E15-E23 -> -308.49328 | F24: =F15-F23 -> -106.58811 | G24: =G15-G23 -> 164.33175 | H24: =H15-H23 -> -36.64045 | I24: =I15-I23 -> 108.85597 | J24: =J15-J23 -> -37.9504 | K24: =K15-K23 -> 107.54746 | L24: =L15-L23 -> 674.46889 | ... AI24: =AI15-AI23 -> -102.21162 | AK24: =AK15-AK23 -> 1141.8737 | AL24: =AL15-AL23 -> 1232.0473 | AM24: =AM15-AM23 -> 1696.5071 | AO24: =IFERROR(AK24/AK$10%,0) -> 14.931486 | AP24: =IFERROR(AL24/AL$10%,0) -> 18.175137 | AQ24: =IFERROR(AM24/AM$10%,0) -> 23.102429
C26: Income taxes | E26: =_xlfn.XLOOKUP($C26,'PL1'!$C:$C,'PL1'!E:E)-SUMIFS(ADJ!G:G,ADJ!$E:$E,'RPL1'!$C26) -> 0 | F26: =_xlfn.XLOOKUP($C26,'PL1'!$C:$C,'PL1'!F:F)-SUMIFS(ADJ!H:H,ADJ!$E:$E,'RPL1'!$C26) -> 0 | G26: =_xlfn.XLOOKUP($C26,'PL1'!$C:$C,'PL1'!G:G)-SUMIFS(ADJ!I:I,ADJ!$E:$E,'RPL1'!$C26) -> 0 | H26: =_xlfn.XLOOKUP($C26,'PL1'!$C:$C,'PL1'!H:H)-SUMIFS(ADJ!J:J,ADJ!$E:$E,'RPL1'!$C26) -> 0 | I26: =_xlfn.XLOOKUP($C26,'PL1'!$C:$C,'PL1'!I:I)-SUMIFS(ADJ!K:K,ADJ!$E:$E,'RPL1'!$C26) -> 0 | J26: =_xlfn.XLOOKUP($C26,'PL1'!$C:$C,'PL1'!J:J)-SUMIFS(ADJ!L:L,ADJ!$E:$E,'RPL1'!$C26) -> 0 | K26: =_xlfn.XLOOKUP($C26,'PL1'!$C:$C,'PL1'!K:K)-SUMIFS(ADJ!M:M,ADJ!$E:$E,'RPL1'!$C26) -> 0 | L26: =_xlfn.XLOOKUP($C26,'PL1'!$C:$C,'PL1'!L:L)-SUMIFS(ADJ!N:N,ADJ!$E:$E,'RPL1'!$C26) -> 0 | M26: =_xlfn.XLOOKUP($C26,'PL1'!$C:$C,'PL1'!M:M)-SUMIFS(ADJ!O:O,ADJ!$E:$E,'RPL1'!$C26) -> 0 | N26: =_xlfn.XLOOKUP($C26,'PL1'!$C:$C,'PL1'!N:N)-SUMIFS(ADJ!P:P,ADJ!$E:$E,'RPL1'!$C26) -> 0 | O26: =_xlfn.XLOOKUP($C26,'PL1'!$C:$C,'PL1'!O:O)-SUMIFS(ADJ!Q:Q,ADJ!$E:$E,'RPL1'!$C26) -> 0 | P26: =_xlfn.XLOOKUP($C26,'PL1'!$C:$C,'PL1'!P:P)-SUMIFS(ADJ!R:R,ADJ!$E:$E,'RPL1'!$C26) -> 0 | Q26: =_xlfn.XLOOKUP($C26,'PL1'!$C:$C,'PL1'!Q:Q)-SUMIFS(ADJ!S:S,ADJ!$E:$E,'RPL1'!$C26) -> 0 | R26: =_xlfn.XLOOKUP($C26,'PL1'!$C:$C,'PL1'!R:R)-SUMIFS(ADJ!T:T,ADJ!$E:$E,'RPL1'!$C26) -> 0 | S26: =_xlfn.XLOOKUP($C26,'PL1'!$C:$C,'PL1'!S:S)-SUMIFS(ADJ!U:U,ADJ!$E:$E,'RPL1'!$C26) -> 0 | T26: =_xlfn.XLOOKUP($C26,'PL1'!$C:$C,'PL1'!T:T)-SUMIFS(ADJ!V:V,ADJ!$E:$E,'RPL1'!$C26) -> 0 | U26: =_xlfn.XLOOKUP($C26,'PL1'!$C:$C,'PL1'!U:U)-SUMIFS(ADJ!W:W,ADJ!$E:$E,'RPL1'!$C26) -> 0 | V26: =_xlfn.XLOOKUP($C26,'PL1'!$C:$C,'PL1'!V:V)-SUMIFS(ADJ!X:X,ADJ!$E:$E,'RPL1'!$C26) -> 0 | W26: =_xlfn.XLOOKUP($C26,'PL1'!$C:$C,'PL1'!W:W)-SUMIFS(ADJ!Y:Y,ADJ!$E:$E,'RPL1'!$C26) -> 0 | X26: =_xlfn.XLOOKUP($C26,'PL1'!$C:$C,'PL1'!X:X)-SUMIFS(ADJ!Z:Z,ADJ!$E:$E,'RPL1'!$C26) -> 0 | Y26: =_xlfn.XLOOKUP($C26,'PL1'!$C:$C,'PL1'!Y:Y)-SUMIFS(ADJ!AA:AA,ADJ!$E:$E,'RPL1'!$C26) -> 0 | Z26: =_xlfn.XLOOKUP($C26,'PL1'!$C:$C,'PL1'!Z:Z)-SUMIFS(ADJ!AB:AB,ADJ!$E:$E,'RPL1'!$C26) -> 0 | AA26: =_xlfn.XLOOKUP($C26,'PL1'!$C:$C,'PL1'!AA:AA)-SUMIFS(ADJ!AC:AC,ADJ!$E:$E,'RPL1'!$C26) -> 0 | AB26: =_xlfn.XLOOKUP($C26,'PL1'!$C:$C,'PL1'!AB:AB)-SUMIFS(ADJ!AD:AD,ADJ!$E:$E,'RPL1'!$C26) -> 0 | AC26: =_xlfn.XLOOKUP($C26,'PL1'!$C:$C,'PL1'!AC:AC)-SUMIFS(ADJ!AE:AE,ADJ!$E:$E,'RPL1'!$C26) -> 0 | AD26: =_xlfn.XLOOKUP($C26,'PL1'!$C:$C,'PL1'!AD:AD)-SUMIFS(ADJ!AF:AF,ADJ!$E:$E,'RPL1'!$C26) -> 0 | AE26: =_xlfn.XLOOKUP($C26,'PL1'!$C:$C,'PL1'!AE:AE)-SUMIFS(ADJ!AG:AG,ADJ!$E:$E,'RPL1'!$C26) -> 0 | AF26: =_xlfn.XLOOKUP($C26,'PL1'!$C:$C,'PL1'!AF:AF)-SUMIFS(ADJ!AH:AH,ADJ!$E:$E,'RPL1'!$C26) -> 0 | AG26: =_xlfn.XLOOKUP($C26,'PL1'!$C:$C,'PL1'!AG:AG)-SUMIFS(ADJ!AI:AI,ADJ!$E:$E,'RPL1'!$C26) -> 0 | AH26: =_xlfn.XLOOKUP($C26,'PL1'!$C:$C,'PL1'!AH:AH)-SUMIFS(ADJ!AJ:AJ,ADJ!$E:$E,'RPL1'!$C26) -> 0 | AI26: =_xlfn.XLOOKUP($C26,'PL1'!$C:$C,'PL1'!AI:AI)-SUMIFS(ADJ!AK:AK,ADJ!$E:$E,'RPL1'!$C26) -> 0 | AK26: =SUM(E26:P26) -> 0 | AL26: =SUM(Q26:AB26) -> 0 | AM26: =SUM(X26:AI26) -> 0 | AO26: =IFERROR(AK26/AK$10%,0) -> 0 | AP26: =IFERROR(AL26/AL$10%,0) -> 0 | AQ26: =IFERROR(AM26/AM$10%,0) -> 0
C27: Depreciation and amortization | E27: =_xlfn.XLOOKUP($C27,'PL1'!$C:$C,'PL1'!E:E)-SUMIFS(ADJ!G:G,ADJ!$E:$E,'RPL1'!$C27) -> 0 | F27: =_xlfn.XLOOKUP($C27,'PL1'!$C:$C,'PL1'!F:F)-SUMIFS(ADJ!H:H,ADJ!$E:$E,'RPL1'!$C27) -> 0 | G27: =_xlfn.XLOOKUP($C27,'PL1'!$C:$C,'PL1'!G:G)-SUMIFS(ADJ!I:I,ADJ!$E:$E,'RPL1'!$C27) -> 0 | H27: =_xlfn.XLOOKUP($C27,'PL1'!$C:$C,'PL1'!H:H)-SUMIFS(ADJ!J:J,ADJ!$E:$E,'RPL1'!$C27) -> 0 | I27: =_xlfn.XLOOKUP($C27,'PL1'!$C:$C,'PL1'!I:I)-SUMIFS(ADJ!K:K,ADJ!$E:$E,'RPL1'!$C27) -> 0 | J27: =_xlfn.XLOOKUP($C27,'PL1'!$C:$C,'PL1'!J:J)-SUMIFS(ADJ!L:L,ADJ!$E:$E,'RPL1'!$C27) -> 0 | K27: =_xlfn.XLOOKUP($C27,'PL1'!$C:$C,'PL1'!K:K)-SUMIFS(ADJ!M:M,ADJ!$E:$E,'RPL1'!$C27) -> 0 | L27: =_xlfn.XLOOKUP($C27,'PL1'!$C:$C,'PL1'!L:L)-SUMIFS(ADJ!N:N,ADJ!$E:$E,'RPL1'!$C27) -> 0 | M27: =_xlfn.XLOOKUP($C27,'PL1'!$C:$C,'PL1'!M:M)-SUMIFS(ADJ!O:O,ADJ!$E:$E,'RPL1'!$C27) -> 0 | N27: =_xlfn.XLOOKUP($C27,'PL1'!$C:$C,'PL1'!N:N)-SUMIFS(ADJ!P:P,ADJ!$E:$E,'RPL1'!$C27) -> 0 | O27: =_xlfn.XLOOKUP($C27,'PL1'!$C:$C,'PL1'!O:O)-SUMIFS(ADJ!Q:Q,ADJ!$E:$E,'RPL1'!$C27) -> 0 | P27: =_xlfn.XLOOKUP($C27,'PL1'!$C:$C,'PL1'!P:P)-SUMIFS(ADJ!R:R,ADJ!$E:$E,'RPL1'!$C27) -> 0 | Q27: =_xlfn.XLOOKUP($C27,'PL1'!$C:$C,'PL1'!Q:Q)-SUMIFS(ADJ!S:S,ADJ!$E:$E,'RPL1'!$C27) -> 0 | R27: =_xlfn.XLOOKUP($C27,'PL1'!$C:$C,'PL1'!R:R)-SUMIFS(ADJ!T:T,ADJ!$E:$E,'RPL1'!$C27) -> 0 | S27: =_xlfn.XLOOKUP($C27,'PL1'!$C:$C,'PL1'!S:S)-SUMIFS(ADJ!U:U,ADJ!$E:$E,'RPL1'!$C27) -> 0 | T27: =_xlfn.XLOOKUP($C27,'PL1'!$C:$C,'PL1'!T:T)-SUMIFS(ADJ!V:V,ADJ!$E:$E,'RPL1'!$C27) -> 0 | U27: =_xlfn.XLOOKUP($C27,'PL1'!$C:$C,'PL1'!U:U)-SUMIFS(ADJ!W:W,ADJ!$E:$E,'RPL1'!$C27) -> 0 | V27: =_xlfn.XLOOKUP($C27,'PL1'!$C:$C,'PL1'!V:V)-SUMIFS(ADJ!X:X,ADJ!$E:$E,'RPL1'!$C27) -> 0 | W27: =_xlfn.XLOOKUP($C27,'PL1'!$C:$C,'PL1'!W:W)-SUMIFS(ADJ!Y:Y,ADJ!$E:$E,'RPL1'!$C27) -> 0 | X27: =_xlfn.XLOOKUP($C27,'PL1'!$C:$C,'PL1'!X:X)-SUMIFS(ADJ!Z:Z,ADJ!$E:$E,'RPL1'!$C27) -> 0 | Y27: =_xlfn.XLOOKUP($C27,'PL1'!$C:$C,'PL1'!Y:Y)-SUMIFS(ADJ!AA:AA,ADJ!$E:$E,'RPL1'!$C27) -> 0 | Z27: =_xlfn.XLOOKUP($C27,'PL1'!$C:$C,'PL1'!Z:Z)-SUMIFS(ADJ!AB:AB,ADJ!$E:$E,'RPL1'!$C27) -> 0 | AA27: =_xlfn.XLOOKUP($C27,'PL1'!$C:$C,'PL1'!AA:AA)-SUMIFS(ADJ!AC:AC,ADJ!$E:$E,'RPL1'!$C27) -> 0 | AB27: =_xlfn.XLOOKUP($C27,'PL1'!$C:$C,'PL1'!AB:AB)-SUMIFS(ADJ!AD:AD,ADJ!$E:$E,'RPL1'!$C27) -> 0 | AC27: =_xlfn.XLOOKUP($C27,'PL1'!$C:$C,'PL1'!AC:AC)-SUMIFS(ADJ!AE:AE,ADJ!$E:$E,'RPL1'!$C27) -> 0 | AD27: =_xlfn.XLOOKUP($C27,'PL1'!$C:$C,'PL1'!AD:AD)-SUMIFS(ADJ!AF:AF,ADJ!$E:$E,'RPL1'!$C27) -> 0 | AE27: =_xlfn.XLOOKUP($C27,'PL1'!$C:$C,'PL1'!AE:AE)-SUMIFS(ADJ!AG:AG,ADJ!$E:$E,'RPL1'!$C27) -> 0 | AF27: =_xlfn.XLOOKUP($C27,'PL1'!$C:$C,'PL1'!AF:AF)-SUMIFS(ADJ!AH:AH,ADJ!$E:$E,'RPL1'!$C27) -> 0 | AG27: =_xlfn.XLOOKUP($C27,'PL1'!$C:$C,'PL1'!AG:AG)-SUMIFS(ADJ!AI:AI,ADJ!$E:$E,'RPL1'!$C27) -> 0 | AH27: =_xlfn.XLOOKUP($C27,'PL1'!$C:$C,'PL1'!AH:AH)-SUMIFS(ADJ!AJ:AJ,ADJ!$E:$E,'RPL1'!$C27) -> 0 | AI27: =_xlfn.XLOOKUP($C27,'PL1'!$C:$C,'PL1'!AI:AI)-SUMIFS(ADJ!AK:AK,ADJ!$E:$E,'RPL1'!$C27) -> 0 | AK27: =SUM(E27:P27) -> 0 | AL27: =SUM(Q27:AB27) -> 0 | AM27: =SUM(X27:AI27) -> 0 | AO27: =IFERROR(AK27/AK$10%,0) -> 0 | AP27: =IFERROR(AL27/AL$10%,0) -> 0 | AQ27: =IFERROR(AM27/AM$10%,0) -> 0
C28: Other non-operating expenses / (income) | E28: =_xlfn.XLOOKUP($C28,'PL1'!$C:$C,'PL1'!E:E)-SUMIFS(ADJ!G:G,ADJ!$E:$E,'RPL1'!$C28) -> 0.4 | F28: =_xlfn.XLOOKUP($C28,'PL1'!$C:$C,'PL1'!F:F)-SUMIFS(ADJ!H:H,ADJ!$E:$E,'RPL1'!$C28) -> 0.4 | G28: =_xlfn.XLOOKUP($C28,'PL1'!$C:$C,'PL1'!G:G)-SUMIFS(ADJ!I:I,ADJ!$E:$E,'RPL1'!$C28) -> 0.4 | H28: =_xlfn.XLOOKUP($C28,'PL1'!$C:$C,'PL1'!H:H)-SUMIFS(ADJ!J:J,ADJ!$E:$E,'RPL1'!$C28) -> -355.14435 | I28: =_xlfn.XLOOKUP($C28,'PL1'!$C:$C,'PL1'!I:I)-SUMIFS(ADJ!K:K,ADJ!$E:$E,'RPL1'!$C28) -> 0.4 | J28: =_xlfn.XLOOKUP($C28,'PL1'!$C:$C,'PL1'!J:J)-SUMIFS(ADJ!L:L,ADJ!$E:$E,'RPL1'!$C28) -> -2 | K28: =_xlfn.XLOOKUP($C28,'PL1'!$C:$C,'PL1'!K:K)-SUMIFS(ADJ!M:M,ADJ!$E:$E,'RPL1'!$C28) -> 0 | L28: =_xlfn.XLOOKUP($C28,'PL1'!$C:$C,'PL1'!L:L)-SUMIFS(ADJ!N:N,ADJ!$E:$E,'RPL1'!$C28) -> 0.1 | M28: =_xlfn.XLOOKUP($C28,'PL1'!$C:$C,'PL1'!M:M)-SUMIFS(ADJ!O:O,ADJ!$E:$E,'RPL1'!$C28) -> 0 | N28: =_xlfn.XLOOKUP($C28,'PL1'!$C:$C,'PL1'!N:N)-SUMIFS(ADJ!P:P,ADJ!$E:$E,'RPL1'!$C28) -> 0 | O28: =_xlfn.XLOOKUP($C28,'PL1'!$C:$C,'PL1'!O:O)-SUMIFS(ADJ!Q:Q,ADJ!$E:$E,'RPL1'!$C28) -> 0 | P28: =_xlfn.XLOOKUP($C28,'PL1'!$C:$C,'PL1'!P:P)-SUMIFS(ADJ!R:R,ADJ!$E:$E,'RPL1'!$C28) -> -76.4 | Q28: =_xlfn.XLOOKUP($C28,'PL1'!$C:$C,'PL1'!Q:Q)-SUMIFS(ADJ!S:S,ADJ!$E:$E,'RPL1'!$C28) -> 0 | R28: =_xlfn.XLOOKUP($C28,'PL1'!$C:$C,'PL1'!R:R)-SUMIFS(ADJ!T:T,ADJ!$E:$E,'RPL1'!$C28) -> 0 | S28: =_xlfn.XLOOKUP($C28,'PL1'!$C:$C,'PL1'!S:S)-SUMIFS(ADJ!U:U,ADJ!$E:$E,'RPL1'!$C28) -> 0 | T28: =_xlfn.XLOOKUP($C28,'PL1'!$C:$C,'PL1'!T:T)-SUMIFS(ADJ!V:V,ADJ!$E:$E,'RPL1'!$C28) -> 0 | U28: =_xlfn.XLOOKUP($C28,'PL1'!$C:$C,'PL1'!U:U)-SUMIFS(ADJ!W:W,ADJ!$E:$E,'RPL1'!$C28) -> 0 | V28: =_xlfn.XLOOKUP($C28,'PL1'!$C:$C,'PL1'!V:V)-SUMIFS(ADJ!X:X,ADJ!$E:$E,'RPL1'!$C28) -> 0 | W28: =_xlfn.XLOOKUP($C28,'PL1'!$C:$C,'PL1'!W:W)-SUMIFS(ADJ!Y:Y,ADJ!$E:$E,'RPL1'!$C28) -> 0 | X28: =_xlfn.XLOOKUP($C28,'PL1'!$C:$C,'PL1'!X:X)-SUMIFS(ADJ!Z:Z,ADJ!$E:$E,'RPL1'!$C28) -> -50 | Y28: =_xlfn.XLOOKUP($C28,'PL1'!$C:$C,'PL1'!Y:Y)-SUMIFS(ADJ!AA:AA,ADJ!$E:$E,'RPL1'!$C28) -> -2.26402 | Z28: =_xlfn.XLOOKUP($C28,'PL1'!$C:$C,'PL1'!Z:Z)-SUMIFS(ADJ!AB:AB,ADJ!$E:$E,'RPL1'!$C28) -> 0 | AA28: =_xlfn.XLOOKUP($C28,'PL1'!$C:$C,'PL1'!AA:AA)-SUMIFS(ADJ!AC:AC,ADJ!$E:$E,'RPL1'!$C28) -> 0 | AB28: =_xlfn.XLOOKUP($C28,'PL1'!$C:$C,'PL1'!AB:AB)-SUMIFS(ADJ!AD:AD,ADJ!$E:$E,'RPL1'!$C28) -> 0 | AC28: =_xlfn.XLOOKUP($C28,'PL1'!$C:$C,'PL1'!AC:AC)-SUMIFS(ADJ!AE:AE,ADJ!$E:$E,'RPL1'!$C28) -> 0 | AD28: =_xlfn.XLOOKUP($C28,'PL1'!$C:$C,'PL1'!AD:AD)-SUMIFS(ADJ!AF:AF,ADJ!$E:$E,'RPL1'!$C28) -> 0 | AE28: =_xlfn.XLOOKUP($C28,'PL1'!$C:$C,'PL1'!AE:AE)-SUMIFS(ADJ!AG:AG,ADJ!$E:$E,'RPL1'!$C28) -> 0 | AF28: =_xlfn.XLOOKUP($C28,'PL1'!$C:$C,'PL1'!AF:AF)-SUMIFS(ADJ!AH:AH,ADJ!$E:$E,'RPL1'!$C28) -> 0 | AG28: =_xlfn.XLOOKUP($C28,'PL1'!$C:$C,'PL1'!AG:AG)-SUMIFS(ADJ!AI:AI,ADJ!$E:$E,'RPL1'!$C28) -> 0 | AH28: =_xlfn.XLOOKUP($C28,'PL1'!$C:$C,'PL1'!AH:AH)-SUMIFS(ADJ!AJ:AJ,ADJ!$E:$E,'RPL1'!$C28) -> 0 | AI28: =_xlfn.XLOOKUP($C28,'PL1'!$C:$C,'PL1'!AI:AI)-SUMIFS(ADJ!AK:AK,ADJ!$E:$E,'RPL1'!$C28) -> 0.10556 | AK28: =SUM(E28:P28) -> -431.84435 | AL28: =SUM(Q28:AB28) -> -52.26402 | AM28: =SUM(X28:AI28) -> -52.15846 | AO28: =IFERROR(AK28/AK$10%,0) -> -5.6469275 | AP28: =IFERROR(AL28/AL$10%,0) -> -0.77099777 | AQ28: =IFERROR(AM28/AM$10%,0) -> -0.71027533
C29: Non-operating expenses / (income) | E29: =SUM(E26:E28) -> 0.4 | F29: =SUM(F26:F28) -> 0.4 | G29: =SUM(G26:G28) -> 0.4 | H29: =SUM(H26:H28) -> -355.14435 | I29: =SUM(I26:I28) -> 0.4 | J29: =SUM(J26:J28) -> -2 | K29: =SUM(K26:K28) -> 0 | L29: =SUM(L26:L28) -> 0.1 | ... AI29: =SUM(AI26:AI28) -> 0.10556 | AK29: =SUM(AK26:AK28) -> -431.84435 | AL29: =SUM(AL26:AL28) -> -52.26402 | AM29: =SUM(AM26:AM28) -> -52.15846 | AO29: =IFERROR(AK29/AK$10%,0) -> -5.6469275 | AP29: =IFERROR(AL29/AL$10%,0) -> -0.77099777 | AQ29: =IFERROR(AM29/AM$10%,0) -> -0.71027533
C30: Adjusted EBITDA | E30: =E24-E29 -> -308.89328 | F30: =F24-F29 -> -106.98811 | G30: =G24-G29 -> 163.93175 | H30: =H24-H29 -> 318.5039 | I30: =I24-I29 -> 108.45597 | J30: =J24-J29 -> -35.9504 | K30: =K24-K29 -> 107.54746 | L30: =L24-L29 -> 674.36889 | ... AI30: =AI24-AI29 -> -102.31718 | AK30: =AK24-AK29 -> 1573.718 | AL30: =AL24-AL29 -> 1284.3113 | AM30: =AM24-AM29 -> 1748.6655 | AO30: =IFERROR(AK30/AK$10%,0) -> 20.578413 | AP30: =IFERROR(AL30/AL$10%,0) -> 18.946135 | AQ30: =IFERROR(AM30/AM$10%,0) -> 23.812704
C32: Gross margin, adjusted (%) | E32: =IFERROR(E15/E$10%,0) -> 100 | F32: =IFERROR(F15/F$10%,0) -> 100 | G32: =IFERROR(G15/G$10%,0) -> 100 | H32: =IFERROR(H15/H$10%,0) -> 100 | I32: =IFERROR(I15/I$10%,0) -> 100 | J32: =IFERROR(J15/J$10%,0) -> 100 | K32: =IFERROR(K15/K$10%,0) -> 100 | L32: =IFERROR(L15/L$10%,0) -> 100 | ... AI32: =IFERROR(AI15/AI$10%,0) -> 100 | AK32: =IFERROR(AK15/AK$10%,0) -> 100 | AL32: =IFERROR(AL15/AL$10%,0) -> 100 | AM32: =IFERROR(AM15/AM$10%,0) -> 100
C33: Operating margin, adjusted (%) | E33: =IFERROR(E24/E$10%,0) -> -159.73597 | F33: =IFERROR(F24/F$10%,0) -> -24.820054 | G33: =IFERROR(G24/G$10%,0) -> 22.455368 | H33: =IFERROR(H24/H$10%,0) -> -8.5140059 | I33: =IFERROR(I24/I$10%,0) -> 17.460845 | J33: =IFERROR(J24/J$10%,0) -> -7.8926691 | K33: =IFERROR(K24/K$10%,0) -> 15.621272 | L33: =IFERROR(L24/L$10%,0) -> 53.216755 | ... AI33: =IFERROR(AI24/AI$10%,0) -> -24.152769 | AK33: =IFERROR(AK24/AK$10%,0) -> 14.931486 | AL33: =IFERROR(AL24/AL$10%,0) -> 18.175137 | AM33: =IFERROR(AM24/AM$10%,0) -> 23.102429
C34: EBITDA margin, adjusted (%) | E34: =IFERROR(E30/E$10%,0) -> -159.94308 | F34: =IFERROR(F30/F$10%,0) -> -24.913198 | G34: =IFERROR(G30/G$10%,0) -> 22.400709 | H34: =IFERROR(H30/H$10%,0) -> 74.009573 | I34: =IFERROR(I30/I$10%,0) -> 17.396684 | J34: =IFERROR(J30/J$10%,0) -> -7.4767226 | K34: =IFERROR(K30/K$10%,0) -> 15.621272 | L34: =IFERROR(L30/L$10%,0) -> 53.208865 | ... AI34: =IFERROR(AI30/AI$10%,0) -> -24.177713 | AK34: =IFERROR(AK30/AK$10%,0) -> 20.578413 | AL34: =IFERROR(AL30/AL$10%,0) -> 18.946135 | AM34: =IFERROR(AM30/AM$10%,0) -> 23.812704
C37: Check QE1 | E37: =+'QE1'!E51-E30 -> 0 | F37: =+'QE1'!F51-F30 -> 0 | G37: =+'QE1'!G51-G30 -> 0 | H37: =+'QE1'!H51-H30 -> 0 | I37: =+'QE1'!I51-I30 -> 0 | J37: =+'QE1'!J51-J30 -> 0 | K37: =+'QE1'!K51-K30 -> 0 | L37: =+'QE1'!L51-L30 -> 0 | ... AI37: =+'QE1'!AI51-AI30 -> 0 | AK37: =+'QE1'!AK51-AK30 -> 0 | AL37: =+'QE1'!AL51-AL30 -> 0 | AM37: =+'QE1'!AM51-AM30 -> 0
C40: Adjusted EBITDA Bridge
C41: FY24 EBITDA | D41: =AK30 -> 1573.718
C42: Gross profit | D42: =AL15-AK15 -> -868.67044
C43: Opex | D43: =AK23-AL23 -> 958.84408
C44: NOE/I | D44: =AK29-AL29 -> -379.58033
C45: FY25 EBITDA | D45: =SUM(D41:D44) -> 1284.3113
C46: Gross profit | D46: =AM15-AL15 -> 564.6631
C47: Opex | D47: =AL23-AM23 -> -100.20335
C48: NOE/I | D48: =AL29-AM29 -> -0.10556
C49: TTM26 EBITDA | D49: =SUM(D45:D48) -> 1748.6655 | E49: =D49-AM30 -> 0

Sheet RPL2
A1: =IF(ROUND(SUM(E31:X35),1)<>0,"NO","Yes") -> Yes | C1: Project X
A2: =IF(COUNTIF(E31:X35,">0.5")+COUNTIF(E31:X35,"<-0.5")<1,"Yes","No") -> Yes | C2: CLIENT
A3: =2-COUNTIF(A1:A2,"Yes") -> 0 | C3: ($ in 000s)
C4: Reported to Adjusted Bridge
I6: Management | J6: Management | K6: Management | M6: Diligence | N6: Diligence | O6: Diligence | Q6: Pro Forma | R6: Pro Forma | S6: Pro Forma
C7: =C4 -> Reported to Adjusted Bridge | E7: Reported Earnings | I7: Management adjustments | M7: Diligence adjustments | Q7: Pro Forma adjustments | U7: Adjusted Earnings
C8: =C3 -> ($ in 000s) | D8: Ref | E8: ='PL1'!AK8 -> FY24 | F8: ='PL1'!AL8 -> FY25 | G8: ='PL1'!AM8 -> TTM26 | I8: =E8 -> FY24 | J8: =F8 -> FY25 | K8: =G8 -> TTM26 | M8: =E8 -> FY24 | N8: =F8 -> FY25 | O8: =G8 -> TTM26 | Q8: =E8 -> FY24 | R8: =F8 -> FY25 | S8: =G8 -> TTM26 | U8: =E8 -> FY24 | V8: =F8 -> FY25 | W8: =G8 -> TTM26
C9: Service revenue | E9: =_xlfn.XLOOKUP($C9,'PL1'!$C:$C,'PL1'!AK:AK) -> 7647.4216 | F9: =_xlfn.XLOOKUP($C9,'PL1'!$C:$C,'PL1'!AL:AL) -> 6778.7512 | G9: =_xlfn.XLOOKUP($C9,'PL1'!$C:$C,'PL1'!AM:AM) -> 7343.4143 | I9: =SUMIFS(ADJ!$AM:$AM,ADJ!$E:$E,'RPL2'!$C9,ADJ!$D:$D,'RPL2'!I$6) -> 0 | J9: =SUMIFS(ADJ!$AN:$AN,ADJ!$E:$E,'RPL2'!$C9,ADJ!$D:$D,'RPL2'!J$6) -> 0 | K9: =SUMIFS(ADJ!$AO:$AO,ADJ!$E:$E,'RPL2'!$C9,ADJ!$D:$D,'RPL2'!K$6) -> 0 | M9: =SUMIFS(ADJ!$AM:$AM,ADJ!$E:$E,'RPL2'!$C9,ADJ!$D:$D,'RPL2'!M$6) -> 0 | N9: =SUMIFS(ADJ!$AN:$AN,ADJ!$E:$E,'RPL2'!$C9,ADJ!$D:$D,'RPL2'!N$6) -> 0 | O9: =SUMIFS(ADJ!$AO:$AO,ADJ!$E:$E,'RPL2'!$C9,ADJ!$D:$D,'RPL2'!O$6) -> 0 | Q9: =SUMIFS(ADJ!$AM:$AM,ADJ!$E:$E,'RPL2'!$C9,ADJ!$D:$D,'RPL2'!Q$6) -> 0 | R9: =SUMIFS(ADJ!$AN:$AN,ADJ!$E:$E,'RPL2'!$C9,ADJ!$D:$D,'RPL2'!R$6) -> 0 | S9: =SUMIFS(ADJ!$AO:$AO,ADJ!$E:$E,'RPL2'!$C9,ADJ!$D:$D,'RPL2'!S$6) -> 0 | U9: =E9+I9+M9+Q9 -> 7647.4216 | V9: =F9+J9+N9+R9 -> 6778.7512 | W9: =G9+K9+O9+S9 -> 7343.4143
C10: Net revenue | E10: =SUM(E9:E9) -> 7647.4216 | F10: =SUM(F9:F9) -> 6778.7512 | G10: =SUM(G9:G9) -> 7343.4143 | I10: =SUM(I9:I9) -> 0 | J10: =SUM(J9:J9) -> 0 | K10: =SUM(K9:K9) -> 0 | M10: =SUM(M9:M9) -> 0 | N10: =SUM(N9:N9) -> 0 | O10: =SUM(O9:O9) -> 0 | Q10: =SUM(Q9:Q9) -> 0 | R10: =SUM(R9:R9) -> 0 | S10: =SUM(S9:S9) -> 0 | U10: =SUM(U9:U9) -> 7647.4216 | V10: =SUM(V9:V9) -> 6778.7512 | W10: =SUM(W9:W9) -> 7343.4143
C12: Cost of goods sold | E12: 0 | F12: 0 | G12: 0 | I12: 0 | J12: 0 | K12: 0 | M12: 0 | N12: 0 | O12: 0 | Q12: 0 | R12: 0 | S12: 0 | U12: =E12+I12+M12+Q12 -> 0 | V12: =F12+J12+N12+R12 -> 0 | W12: =G12+K12+O12+S12 -> 0
C13: Gross profit | E13: =E10-E12 -> 7647.4216 | F13: =F10-F12 -> 6778.7512 | G13: =G10-G12 -> 7343.4143 | I13: =I10-I12 -> 0 | J13: =J10-J12 -> 0 | K13: =K10-K12 -> 0 | M13: =M10-M12 -> 0 | N13: =N10-N12 -> 0 | O13: =O10-O12 -> 0 | Q13: =Q10-Q12 -> 0 | R13: =R10-R12 -> 0 | S13: =S10-S12 -> 0 | U13: =U10-U12 -> 7647.4216 | V13: =V10-V12 -> 6778.7512 | W13: =W10-W12 -> 7343.4143
C15: Payroll and benefits | E15: =_xlfn.XLOOKUP($C15,'PL1'!$C:$C,'PL1'!AK:AK) -> 3426.1163 | F15: =_xlfn.XLOOKUP($C15,'PL1'!$C:$C,'PL1'!AL:AL) -> 2775.2378 | G15: =_xlfn.XLOOKUP($C15,'PL1'!$C:$C,'PL1'!AM:AM) -> 2733.5666 | I15: =-SUMIFS(ADJ!$AM:$AM,ADJ!$E:$E,'RPL2'!$C15,ADJ!$D:$D,'RPL2'!I$6) -> 0 | J15: =-SUMIFS(ADJ!$AN:$AN,ADJ!$E:$E,'RPL2'!$C15,ADJ!$D:$D,'RPL2'!J$6) -> 0 | K15: =-SUMIFS(ADJ!$AO:$AO,ADJ!$E:$E,'RPL2'!$C15,ADJ!$D:$D,'RPL2'!K$6) -> 0 | M15: =-SUMIFS(ADJ!$AM:$AM,ADJ!$E:$E,'RPL2'!$C15,ADJ!$D:$D,'RPL2'!M$6) -> 0 | N15: =-SUMIFS(ADJ!$AN:$AN,ADJ!$E:$E,'RPL2'!$C15,ADJ!$D:$D,'RPL2'!N$6) -> 0 | O15: =-SUMIFS(ADJ!$AO:$AO,ADJ!$E:$E,'RPL2'!$C15,ADJ!$D:$D,'RPL2'!O$6) -> 0 | Q15: =-SUMIFS(ADJ!$AM:$AM,ADJ!$E:$E,'RPL2'!$C15,ADJ!$D:$D,'RPL2'!Q$6) -> 0 | R15: =-SUMIFS(ADJ!$AN:$AN,ADJ!$E:$E,'RPL2'!$C15,ADJ!$D:$D,'RPL2'!R$6) -> 0 | S15: =-SUMIFS(ADJ!$AO:$AO,ADJ!$E:$E,'RPL2'!$C15,ADJ!$D:$D,'RPL2'!S$6) -> 0 | U15: =E15+I15+M15+Q15 -> 3426.1163 | V15: =F15+J15+N15+R15 -> 2775.2378 | W15: =G15+K15+O15+S15 -> 2733.5666
C16: Subcontractor expense | E16: =_xlfn.XLOOKUP($C16,'PL1'!$C:$C,'PL1'!AK:AK) -> 2564.2804 | F16: =_xlfn.XLOOKUP($C16,'PL1'!$C:$C,'PL1'!AL:AL) -> 2169.8976 | G16: =_xlfn.XLOOKUP($C16,'PL1'!$C:$C,'PL1'!AM:AM) -> 2348.0549 | I16: =-SUMIFS(ADJ!$AM:$AM,ADJ!$E:$E,'RPL2'!$C16,ADJ!$D:$D,'RPL2'!I$6) -> 0 | J16: =-SUMIFS(ADJ!$AN:$AN,ADJ!$E:$E,'RPL2'!$C16,ADJ!$D:$D,'RPL2'!J$6) -> 0 | K16: =-SUMIFS(ADJ!$AO:$AO,ADJ!$E:$E,'RPL2'!$C16,ADJ!$D:$D,'RPL2'!K$6) -> 0 | M16: =-SUMIFS(ADJ!$AM:$AM,ADJ!$E:$E,'RPL2'!$C16,ADJ!$D:$D,'RPL2'!M$6) -> 0 | N16: =-SUMIFS(ADJ!$AN:$AN,ADJ!$E:$E,'RPL2'!$C16,ADJ!$D:$D,'RPL2'!N$6) -> 0 | O16: =-SUMIFS(ADJ!$AO:$AO,ADJ!$E:$E,'RPL2'!$C16,ADJ!$D:$D,'RPL2'!O$6) -> 0 | Q16: =-SUMIFS(ADJ!$AM:$AM,ADJ!$E:$E,'RPL2'!$C16,ADJ!$D:$D,'RPL2'!Q$6) -> 0 | R16: =-SUMIFS(ADJ!$AN:$AN,ADJ!$E:$E,'RPL2'!$C16,ADJ!$D:$D,'RPL2'!R$6) -> 0 | S16: =-SUMIFS(ADJ!$AO:$AO,ADJ!$E:$E,'RPL2'!$C16,ADJ!$D:$D,'RPL2'!S$6) -> 0 | U16: =E16+I16+M16+Q16 -> 2564.2804 | V16: =F16+J16+N16+R16 -> 2169.8976 | W16: =G16+K16+O16+S16 -> 2348.0549
C17: Insurance expenses | E17: =_xlfn.XLOOKUP($C17,'PL1'!$C:$C,'PL1'!AK:AK) -> 274.47197 | F17: =_xlfn.XLOOKUP($C17,'PL1'!$C:$C,'PL1'!AL:AL) -> 323.99789 | G17: =_xlfn.XLOOKUP($C17,'PL1'!$C:$C,'PL1'!AM:AM) -> 236.34792 | I17: =-SUMIFS(ADJ!$AM:$AM,ADJ!$E:$E,'RPL2'!$C17,ADJ!$D:$D,'RPL2'!I$6) -> 0 | J17: =-SUMIFS(ADJ!$AN:$AN,ADJ!$E:$E,'RPL2'!$C17,ADJ!$D:$D,'RPL2'!J$6) -> 0 | K17: =-SUMIFS(ADJ!$AO:$AO,ADJ!$E:$E,'RPL2'!$C17,ADJ!$D:$D,'RPL2'!K$6) -> 0 | M17: =-SUMIFS(ADJ!$AM:$AM,ADJ!$E:$E,'RPL2'!$C17,ADJ!$D:$D,'RPL2'!M$6) -> 0 | N17: =-SUMIFS(ADJ!$AN:$AN,ADJ!$E:$E,'RPL2'!$C17,ADJ!$D:$D,'RPL2'!N$6) -> 0 | O17: =-SUMIFS(ADJ!$AO:$AO,ADJ!$E:$E,'RPL2'!$C17,ADJ!$D:$D,'RPL2'!O$6) -> 0 | Q17: =-SUMIFS(ADJ!$AM:$AM,ADJ!$E:$E,'RPL2'!$C17,ADJ!$D:$D,'RPL2'!Q$6) -> 0 | R17: =-SUMIFS(ADJ!$AN:$AN,ADJ!$E:$E,'RPL2'!$C17,ADJ!$D:$D,'RPL2'!R$6) -> 0 | S17: =-SUMIFS(ADJ!$AO:$AO,ADJ!$E:$E,'RPL2'!$C17,ADJ!$D:$D,'RPL2'!S$6) -> 0 | U17: =E17+I17+M17+Q17 -> 274.47197 | V17: =F17+J17+N17+R17 -> 323.99789 | W17: =G17+K17+O17+S17 -> 236.34792
C18: Professional fees | E18: =_xlfn.XLOOKUP($C18,'PL1'!$C:$C,'PL1'!AK:AK) -> 103.35 | F18: =_xlfn.XLOOKUP($C18,'PL1'!$C:$C,'PL1'!AL:AL) -> 153.54457 | G18: =_xlfn.XLOOKUP($C18,'PL1'!$C:$C,'PL1'!AM:AM) -> 186.6898 | I18: =-SUMIFS(ADJ!$AM:$AM,ADJ!$E:$E,'RPL2'!$C18,ADJ!$D:$D,'RPL2'!I$6) -> 0 | J18: =-SUMIFS(ADJ!$AN:$AN,ADJ!$E:$E,'RPL2'!$C18,ADJ!$D:$D,'RPL2'!J$6) -> 0 | K18: =-SUMIFS(ADJ!$AO:$AO,ADJ!$E:$E,'RPL2'!$C18,ADJ!$D:$D,'RPL2'!K$6) -> 0 | M18: =-SUMIFS(ADJ!$AM:$AM,ADJ!$E:$E,'RPL2'!$C18,ADJ!$D:$D,'RPL2'!M$6) -> 0 | N18: =-SUMIFS(ADJ!$AN:$AN,ADJ!$E:$E,'RPL2'!$C18,ADJ!$D:$D,'RPL2'!N$6) -> 0 | O18: =-SUMIFS(ADJ!$AO:$AO,ADJ!$E:$E,'RPL2'!$C18,ADJ!$D:$D,'RPL2'!O$6) -> 0 | Q18: =-SUMIFS(ADJ!$AM:$AM,ADJ!$E:$E,'RPL2'!$C18,ADJ!$D:$D,'RPL2'!Q$6) -> 0 | R18: =-SUMIFS(ADJ!$AN:$AN,ADJ!$E:$E,'RPL2'!$C18,ADJ!$D:$D,'RPL2'!R$6) -> 0 | S18: =-SUMIFS(ADJ!$AO:$AO,ADJ!$E:$E,'RPL2'!$C18,ADJ!$D:$D,'RPL2'!S$6) -> 0 | U18: =E18+I18+M18+Q18 -> 103.35 | V18: =F18+J18+N18+R18 -> 153.54457 | W18: =G18+K18+O18+S18 -> 186.6898
C19: Other operating expenses | E19: =_xlfn.XLOOKUP($C19,'PL1'!$C:$C,'PL1'!AK:AK) -> 113.9614 | F19: =_xlfn.XLOOKUP($C19,'PL1'!$C:$C,'PL1'!AL:AL) -> 103.58166 | G19: =_xlfn.XLOOKUP($C19,'PL1'!$C:$C,'PL1'!AM:AM) -> 111.18032 | I19: =-SUMIFS(ADJ!$AM:$AM,ADJ!$E:$E,'RPL2'!$C19,ADJ!$D:$D,'RPL2'!I$6) -> 0 | J19: =-SUMIFS(ADJ!$AN:$AN,ADJ!$E:$E,'RPL2'!$C19,ADJ!$D:$D,'RPL2'!J$6) -> 0 | K19: =-SUMIFS(ADJ!$AO:$AO,ADJ!$E:$E,'RPL2'!$C19,ADJ!$D:$D,'RPL2'!K$6) -> 0 | M19: =-SUMIFS(ADJ!$AM:$AM,ADJ!$E:$E,'RPL2'!$C19,ADJ!$D:$D,'RPL2'!M$6) -> 0 | N19: =-SUMIFS(ADJ!$AN:$AN,ADJ!$E:$E,'RPL2'!$C19,ADJ!$D:$D,'RPL2'!N$6) -> 0 | O19: =-SUMIFS(ADJ!$AO:$AO,ADJ!$E:$E,'RPL2'!$C19,ADJ!$D:$D,'RPL2'!O$6) -> 0 | Q19: =-SUMIFS(ADJ!$AM:$AM,ADJ!$E:$E,'RPL2'!$C19,ADJ!$D:$D,'RPL2'!Q$6) -> 0 | R19: =-SUMIFS(ADJ!$AN:$AN,ADJ!$E:$E,'RPL2'!$C19,ADJ!$D:$D,'RPL2'!R$6) -> 0 | S19: =-SUMIFS(ADJ!$AO:$AO,ADJ!$E:$E,'RPL2'!$C19,ADJ!$D:$D,'RPL2'!S$6) -> 0 | U19: =E19+I19+M19+Q19 -> 113.9614 | V19: =F19+J19+N19+R19 -> 103.58166 | W19: =G19+K19+O19+S19 -> 111.18032
C20: Travel, meals, and entertainment | E20: =_xlfn.XLOOKUP($C20,'PL1'!$C:$C,'PL1'!AK:AK) -> 23.36787 | F20: =_xlfn.XLOOKUP($C20,'PL1'!$C:$C,'PL1'!AL:AL) -> 20.44433 | G20: =_xlfn.XLOOKUP($C20,'PL1'!$C:$C,'PL1'!AM:AM) -> 31.06769 | I20: =-SUMIFS(ADJ!$AM:$AM,ADJ!$E:$E,'RPL2'!$C20,ADJ!$D:$D,'RPL2'!I$6) -> 0 | J20: =-SUMIFS(ADJ!$AN:$AN,ADJ!$E:$E,'RPL2'!$C20,ADJ!$D:$D,'RPL2'!J$6) -> 0 | K20: =-SUMIFS(ADJ!$AO:$AO,ADJ!$E:$E,'RPL2'!$C20,ADJ!$D:$D,'RPL2'!K$6) -> 0 | M20: =-SUMIFS(ADJ!$AM:$AM,ADJ!$E:$E,'RPL2'!$C20,ADJ!$D:$D,'RPL2'!M$6) -> 0 | N20: =-SUMIFS(ADJ!$AN:$AN,ADJ!$E:$E,'RPL2'!$C20,ADJ!$D:$D,'RPL2'!N$6) -> 0 | O20: =-SUMIFS(ADJ!$AO:$AO,ADJ!$E:$E,'RPL2'!$C20,ADJ!$D:$D,'RPL2'!O$6) -> 0 | Q20: =-SUMIFS(ADJ!$AM:$AM,ADJ!$E:$E,'RPL2'!$C20,ADJ!$D:$D,'RPL2'!Q$6) -> 0 | R20: =-SUMIFS(ADJ!$AN:$AN,ADJ!$E:$E,'RPL2'!$C20,ADJ!$D:$D,'RPL2'!R$6) -> 0 | S20: =-SUMIFS(ADJ!$AO:$AO,ADJ!$E:$E,'RPL2'!$C20,ADJ!$D:$D,'RPL2'!S$6) -> 0 | U20: =E20+I20+M20+Q20 -> 23.36787 | V20: =F20+J20+N20+R20 -> 20.44433 | W20: =G20+K20+O20+S20 -> 31.06769
C21: Operating expenses | E21: =SUM(E15:E20) -> 6505.5479 | F21: =SUM(F15:F20) -> 5546.7039 | G21: =SUM(G15:G20) -> 5646.9072 | I21: =SUM(I15:I20) -> 0 | J21: =SUM(J15:J20) -> 0 | K21: =SUM(K15:K20) -> 0 | M21: =SUM(M15:M20) -> 0 | N21: =SUM(N15:N20) -> 0 | O21: =SUM(O15:O20) -> 0 | Q21: =SUM(Q15:Q20) -> 0 | R21: =SUM(R15:R20) -> 0 | S21: =SUM(S15:S20) -> 0 | U21: =SUM(U15:U20) -> 6505.5479 | V21: =SUM(V15:V20) -> 5546.7039 | W21: =SUM(W15:W20) -> 5646.9072
C22: Operating profit | E22: =E13-E21 -> 1141.8737 | F22: =F13-F21 -> 1232.0473 | G22: =G13-G21 -> 1696.5071 | I22: =I13-I21 -> 0 | J22: =J13-J21 -> 0 | K22: =K13-K21 -> 0 | M22: =M13-M21 -> 0 | N22: =N13-N21 -> 0 | O22: =O13-O21 -> 0 | Q22: =Q13-Q21 -> 0 | R22: =R13-R21 -> 0 | S22: =S13-S21 -> 0 | U22: =U13-U21 -> 1141.8737 | V22: =V13-V21 -> 1232.0473 | W22: =W13-W21 -> 1696.5071
C24: Income taxes | E24: =_xlfn.XLOOKUP($C24,'PL1'!$C:$C,'PL1'!AK:AK) -> 1.5 | F24: =_xlfn.XLOOKUP($C24,'PL1'!$C:$C,'PL1'!AL:AL) -> 182.064 | G24: =_xlfn.XLOOKUP($C24,'PL1'!$C:$C,'PL1'!AM:AM) -> 167.11 | I24: =-SUMIFS(ADJ!$AM:$AM,ADJ!$E:$E,'RPL2'!$C24,ADJ!$D:$D,'RPL2'!I$6) -> -1.5 | J24: =-SUMIFS(ADJ!$AN:$AN,ADJ!$E:$E,'RPL2'!$C24,ADJ!$D:$D,'RPL2'!J$6) -> -182.064 | K24: =-SUMIFS(ADJ!$AO:$AO,ADJ!$E:$E,'RPL2'!$C24,ADJ!$D:$D,'RPL2'!K$6) -> -167.11 | M24: =-SUMIFS(ADJ!$AM:$AM,ADJ!$E:$E,'RPL2'!$C24,ADJ!$D:$D,'RPL2'!M$6) -> 0 | N24: =-SUMIFS(ADJ!$AN:$AN,ADJ!$E:$E,'RPL2'!$C24,ADJ!$D:$D,'RPL2'!N$6) -> 0 | O24: =-SUMIFS(ADJ!$AO:$AO,ADJ!$E:$E,'RPL2'!$C24,ADJ!$D:$D,'RPL2'!O$6) -> 0 | Q24: =-SUMIFS(ADJ!$AM:$AM,ADJ!$E:$E,'RPL2'!$C24,ADJ!$D:$D,'RPL2'!Q$6) -> 0 | R24: =-SUMIFS(ADJ!$AN:$AN,ADJ!$E:$E,'RPL2'!$C24,ADJ!$D:$D,'RPL2'!R$6) -> 0 | S24: =-SUMIFS(ADJ!$AO:$AO,ADJ!$E:$E,'RPL2'!$C24,ADJ!$D:$D,'RPL2'!S$6) -> 0 | U24: =E24+I24+M24+Q24 -> 0 | V24: =F24+J24+N24+R24 -> 0 | W24: =G24+K24+O24+S24 -> 0
C25: Depreciation and amortization | E25: =_xlfn.XLOOKUP($C25,'PL1'!$C:$C,'PL1'!AK:AK) -> 4.448 | F25: =_xlfn.XLOOKUP($C25,'PL1'!$C:$C,'PL1'!AL:AL) -> 3.516 | G25: =_xlfn.XLOOKUP($C25,'PL1'!$C:$C,'PL1'!AM:AM) -> 3.516 | I25: =-SUMIFS(ADJ!$AM:$AM,ADJ!$E:$E,'RPL2'!$C25,ADJ!$D:$D,'RPL2'!I$6) -> -4.448 | J25: =-SUMIFS(ADJ!$AN:$AN,ADJ!$E:$E,'RPL2'!$C25,ADJ!$D:$D,'RPL2'!J$6) -> -3.516 | K25: =-SUMIFS(ADJ!$AO:$AO,ADJ!$E:$E,'RPL2'!$C25,ADJ!$D:$D,'RPL2'!K$6) -> -3.516 | M25: =-SUMIFS(ADJ!$AM:$AM,ADJ!$E:$E,'RPL2'!$C25,ADJ!$D:$D,'RPL2'!M$6) -> 0 | N25: =-SUMIFS(ADJ!$AN:$AN,ADJ!$E:$E,'RPL2'!$C25,ADJ!$D:$D,'RPL2'!N$6) -> 0 | O25: =-SUMIFS(ADJ!$AO:$AO,ADJ!$E:$E,'RPL2'!$C25,ADJ!$D:$D,'RPL2'!O$6) -> 0 | Q25: =-SUMIFS(ADJ!$AM:$AM,ADJ!$E:$E,'RPL2'!$C25,ADJ!$D:$D,'RPL2'!Q$6) -> 0 | R25: =-SUMIFS(ADJ!$AN:$AN,ADJ!$E:$E,'RPL2'!$C25,ADJ!$D:$D,'RPL2'!R$6) -> 0 | S25: =-SUMIFS(ADJ!$AO:$AO,ADJ!$E:$E,'RPL2'!$C25,ADJ!$D:$D,'RPL2'!S$6) -> 0 | U25: =E25+I25+M25+Q25 -> 0 | V25: =F25+J25+N25+R25 -> 0 | W25: =G25+K25+O25+S25 -> 0
C26: Other non-operating expenses / (income) | E26: =_xlfn.XLOOKUP($C26,'PL1'!$C:$C,'PL1'!AK:AK) -> -431.84435 | F26: =_xlfn.XLOOKUP($C26,'PL1'!$C:$C,'PL1'!AL:AL) -> -52.26402 | G26: =_xlfn.XLOOKUP($C26,'PL1'!$C:$C,'PL1'!AM:AM) -> -52.15846 | I26: =-SUMIFS(ADJ!$AM:$AM,ADJ!$E:$E,'RPL2'!$C26,ADJ!$D:$D,'RPL2'!I$6) -> 0 | J26: =-SUMIFS(ADJ!$AN:$AN,ADJ!$E:$E,'RPL2'!$C26,ADJ!$D:$D,'RPL2'!J$6) -> 0 | K26: =-SUMIFS(ADJ!$AO:$AO,ADJ!$E:$E,'RPL2'!$C26,ADJ!$D:$D,'RPL2'!K$6) -> 0 | M26: =-SUMIFS(ADJ!$AM:$AM,ADJ!$E:$E,'RPL2'!$C26,ADJ!$D:$D,'RPL2'!M$6) -> 0 | N26: =-SUMIFS(ADJ!$AN:$AN,ADJ!$E:$E,'RPL2'!$C26,ADJ!$D:$D,'RPL2'!N$6) -> 0 | O26: =-SUMIFS(ADJ!$AO:$AO,ADJ!$E:$E,'RPL2'!$C26,ADJ!$D:$D,'RPL2'!O$6) -> 0 | Q26: =-SUMIFS(ADJ!$AM:$AM,ADJ!$E:$E,'RPL2'!$C26,ADJ!$D:$D,'RPL2'!Q$6) -> 0 | R26: =-SUMIFS(ADJ!$AN:$AN,ADJ!$E:$E,'RPL2'!$C26,ADJ!$D:$D,'RPL2'!R$6) -> 0 | S26: =-SUMIFS(ADJ!$AO:$AO,ADJ!$E:$E,'RPL2'!$C26,ADJ!$D:$D,'RPL2'!S$6) -> 0 | U26: =E26+I26+M26+Q26 -> -431.84435 | V26: =F26+J26+N26+R26 -> -52.26402 | W26: =G26+K26+O26+S26 -> -52.15846
C27: Non-operating expenses / (income) | E27: =SUM(E24:E26) -> -425.89635 | F27: =SUM(F24:F26) -> 133.31598 | G27: =SUM(G24:G26) -> 118.46754 | I27: =SUM(I24:I26) -> -5.948 | J27: =SUM(J24:J26) -> -185.58 | K27: =SUM(K24:K26) -> -170.626 | M27: =SUM(M24:M26) -> 0 | N27: =SUM(N24:N26) -> 0 | O27: =SUM(O24:O26) -> 0 | Q27: =SUM(Q24:Q26) -> 0 | R27: =SUM(R24:R26) -> 0 | S27: =SUM(S24:S26) -> 0 | U27: =SUM(U24:U26) -> -431.84435 | V27: =SUM(V24:V26) -> -52.26402 | W27: =SUM(W24:W26) -> -52.15846
C28: Net Income to Adjusted EBITDA | E28: =E22-E27 -> 1567.77 | F28: =F22-F27 -> 1098.7313 | G28: =G22-G27 -> 1578.0395 | I28: =I22-I27 -> 5.948 | J28: =J22-J27 -> 185.58 | K28: =K22-K27 -> 170.626 | M28: =M22-M27 -> 0 | N28: =N22-N27 -> 0 | O28: =O22-O27 -> 0 | Q28: =Q22-Q27 -> 0 | R28: =R22-R27 -> 0 | S28: =S22-S27 -> 0 | U28: =U22-U27 -> 1573.718 | V28: =V22-V27 -> 1284.3113 | W28: =W22-W27 -> 1748.6655
C31: Check Net income | E31: ='PL1'!AK30-E28 -> 0 | F31: ='PL1'!AL30-F28 -> 0 | G31: ='PL1'!AM30-G28 -> 0
C32: Check EBITDA, management | I32: =('QE1'!AK21+SUM('QE1'!AK10:AK12))-I28 -> 0 | J32: =('QE1'!AL21+SUM('QE1'!AL10:AL12))-J28 -> 0 | K32: =('QE1'!AM21+SUM('QE1'!AM10:AM12))-K28 -> 0
C33: Check EBITDA, diligence | M33: ='QE1'!AK41-M28 -> 0 | N33: ='QE1'!AL41-N28 -> 0 | O33: ='QE1'!AM41-O28 -> 0
C34: Check EBITDA, pro forma | Q34: ='QE1'!AK50-Q28 -> 0 | R34: ='QE1'!AL50-R28 -> 0 | S34: ='QE1'!AM50-S28 -> 0
C35: Check EBITDA, adjusted | U35: ='QE1'!AK51-U28 -> 0 | V35: ='QE1'!AL51-V28 -> 0 | W35: ='QE1'!AM51-W28 -> 0

Sheet QE>>
D8: Project X
D9: CLIENT
D10: Quality of Earnings Analysis

Sheet QE1
A1: =IF(ROUND(SUM(E103:AN105),1)<>0,"NO","Yes") -> Yes | C1: Project X | AX1: Open
A2: =IF(COUNTIF(E103:AN105,">0.5")+COUNTIF(E103:AN105,"<-0.5")<1,"Yes","No") -> Yes | C2: CLIENT | AX2: Completed
A3: =2-COUNTIF(A1:A2,"Yes") -> 0 | C3: ($ in 000s) | AX3: Needs Review
C4: Quality of Earnings Analysis | AX4: In Progress
C7: =C4 -> Quality of Earnings Analysis | E7: FY24 | Q7: FY25 | AC7: FY26 | AM7: =AI8 -> 45961
C8: =C3 -> ($ in 000s) | D8: Ref | E8: =TB!K1 -> 45046 | F8: =TB!L1 -> 45077 | G8: =TB!M1 -> 45107 | H8: =TB!N1 -> 45138 | I8: =TB!O1 -> 45169 | J8: =TB!P1 -> 45199 | K8: =TB!Q1 -> 45230 | L8: =TB!R1 -> 45260 | ... AI8: =TB!AO1 -> 45961 | AK8: ='PL1'!AK8 -> FY24 | AL8: ='PL1'!AL8 -> FY25 | AM8: ='PL1'!AM8 -> TTM26 | AO8: Status | AP8: Owner | AQ8: Due Date | AR8: Reviewer | AS8: Notes
C9: Net income | E9: =+'PL1'!E30 -> -308.89328 | F9: =+'PL1'!F30 -> -106.98811 | G9: =+'PL1'!G30 -> 163.55675 | H9: =+'PL1'!H30 -> 318.5039 | I9: =+'PL1'!I30 -> 108.45597 | J9: =+'PL1'!J30 -> -36.3254 | K9: =+'PL1'!K30 -> 107.54746 | L9: =+'PL1'!L30 -> 674.36889 | ... AI9: =+'PL1'!AI30 -> -102.31718 | AK9: =SUM(E9:P9) -> 1567.77 | AL9: =SUM(Q9:AB9) -> 1098.7313 | AM9: =SUM(X9:AI9) -> 1578.0395
C10: Interest expense, net | E10: =+'PL1'!E33 -> 0 | F10: =+'PL1'!F33 -> 0 | G10: =+'PL1'!G33 -> 0 | H10: =+'PL1'!H33 -> 0 | I10: =+'PL1'!I33 -> 0 | J10: =+'PL1'!J33 -> 0 | K10: =+'PL1'!K33 -> 0 | L10: =+'PL1'!L33 -> 0 | ... AI10: =+'PL1'!AI33 -> 0 | AK10: =SUM(E10:P10) -> 0 | AL10: =SUM(Q10:AB10) -> 0 | AM10: =SUM(X10:AI10) -> 0
C11: Income taxes | E11: =+'PL1'!E34 -> 0 | F11: =+'PL1'!F34 -> 0 | G11: =+'PL1'!G34 -> 0.375 | H11: =+'PL1'!H34 -> 0 | I11: =+'PL1'!I34 -> 0 | J11: =+'PL1'!J34 -> 0.375 | K11: =+'PL1'!K34 -> 0 | L11: =+'PL1'!L34 -> 0 | ... AI11: =+'PL1'!AI34 -> 0 | AK11: =SUM(E11:P11) -> 1.5 | AL11: =SUM(Q11:AB11) -> 182.064 | AM11: =SUM(X11:AI11) -> 167.11
C12: Depreciation and amortization | E12: =+'PL1'!E35 -> 0 | F12: =+'PL1'!F35 -> 0 | G12: =+'PL1'!G35 -> 0 | H12: =+'PL1'!H35 -> 0 | I12: =+'PL1'!I35 -> 0 | J12: =+'PL1'!J35 -> 0 | K12: =+'PL1'!K35 -> 0 | L12: =+'PL1'!L35 -> 0 | ... AI12: =+'PL1'!AI35 -> 0 | AK12: =SUM(E12:P12) -> 4.448 | AL12: =SUM(Q12:AB12) -> 3.516 | AM12: =SUM(X12:AI12) -> 3.516
C13: EBITDA, reported | E13: =SUM(E9:E12) -> -308.89328 | F13: =SUM(F9:F12) -> -106.98811 | G13: =SUM(G9:G12) -> 163.93175 | H13: =SUM(H9:H12) -> 318.5039 | I13: =SUM(I9:I12) -> 108.45597 | J13: =SUM(J9:J12) -> -35.9504 | K13: =SUM(K9:K12) -> 107.54746 | L13: =SUM(L9:L12) -> 674.36889 | ... AI13: =SUM(AI9:AI12) -> -102.31718 | AK13: =SUM(AK9:AK12) -> 1573.718 | AL13: =SUM(AL9:AL12) -> 1284.3113 | AM13: =SUM(AM9:AM12) -> 1748.6655
C15: Management adjustments:
C16: [open] | D16: [A] | AK16: =SUM(E16:P16) -> 0 | AL16: =SUM(Q16:AB16) -> 0 | AM16: =SUM(X16:AI16) -> 0 | AO16: Open
C17: [open] | D17: [B] | AK17: =SUM(E17:P17) -> 0 | AL17: =SUM(Q17:AB17) -> 0 | AM17: =SUM(X17:AI17) -> 0 | AO17: Open
C18: [open] | D18: [C] | AK18: =SUM(E18:P18) -> 0 | AL18: =SUM(Q18:AB18) -> 0 | AM18: =SUM(X18:AI18) -> 0 | AO18: Open
C19: [open] | D19: [D] | AK19: =SUM(E19:P19) -> 0 | AL19: =SUM(Q19:AB19) -> 0 | AM19: =SUM(X19:AI19) -> 0 | AO19: Open
C20: [open] | D20: [E] | AK20: =SUM(E20:P20) -> 0 | AL20: =SUM(Q20:AB20) -> 0 | AM20: =SUM(X20:AI20) -> 0 | AO20: Open
C21: Total Management adjustments | E21: =SUM(E16:E20) -> 0 | F21: =SUM(F16:F20) -> 0 | G21: =SUM(G16:G20) -> 0 | H21: =SUM(H16:H20) -> 0 | I21: =SUM(I16:I20) -> 0 | J21: =SUM(J16:J20) -> 0 | K21: =SUM(K16:K20) -> 0 | L21: =SUM(L16:L20) -> 0 | ... AI21: =SUM(AI16:AI20) -> 0 | AK21: =SUM(AK16:AK20) -> 0 | AL21: =SUM(AL16:AL20) -> 0 | AM21: =SUM(AM16:AM20) -> 0
